[2016-11-03 13:06:48 +0200] [10754] [DEBUG] Current configuration:
  worker_int: <function WorkerInt.worker_int at 0x7facb73c6e18>
  timeout: 30
  ssl_version: 3
  pre_fork: <function Prefork.pre_fork at 0x7facb73c6950>
  certfile: None
  paste: None
  on_exit: <function OnExit.on_exit at 0x7facb73d0950>
  limit_request_line: 4094
  do_handshake_on_connect: False
  post_request: <function PostRequest.post_request at 0x7facb73d0488>
  umask: 0
  cert_reqs: 0
  accesslog: /home/django/source/edc-pharma/logs/gunicorn-access.log
  logger_class: gunicorn.glogging.Logger
  ca_certs: None
  capture_output: False
  pidfile: logs/gunicorn.pid
  loglevel: debug
  workers: 1
  config: gunicorn.conf.py
  limit_request_field_size: 8190
  spew: False
  on_starting: <function OnStarting.on_starting at 0x7facb73c6488>
  worker_abort: <function WorkerAbort.worker_abort at 0x7facb73d0048>
  pre_request: <function PreRequest.pre_request at 0x7facb73d0378>
  errorlog: /home/django/source/edc-pharma/logs/gunicorn-error.log
  when_ready: <function WhenReady.when_ready at 0x7facb73c67b8>
  raw_env: []
  post_fork: <function Postfork.post_fork at 0x7facb73c6ae8>
  tmp_upload_dir: None
  ciphers: TLSv1
  access_log_format: %(h)s %(l)s %(u)s %(t)s "%(r)s" %(s)s %(b)s "%(f)s" "%(a)s"
  backlog: 2048
  keyfile: None
  syslog_addr: udp://localhost:514
  syslog_prefix: None
  proxy_allow_ips: ['127.0.0.1']
  syslog: False
  statsd_host: None
  max_requests: 0
  pre_exec: <function PreExec.pre_exec at 0x7facb73d01e0>
  daemon: True
  group: 1004
  post_worker_init: <function PostWorkerInit.post_worker_init at 0x7facb73c6c80>
  worker_class: sync
  statsd_prefix: 
  nworkers_changed: <function NumWorkersChanged.nworkers_changed at 0x7facb73d07b8>
  threads: 1
  worker_connections: 1000
  max_requests_jitter: 0
  graceful_timeout: 30
  proc_name: None
  secure_scheme_headers: {'X-FORWARDED-PROTO': 'https', 'X-FORWARDED-PROTOCOL': 'ssl', 'X-FORWARDED-SSL': 'on'}
  bind: ['127.0.0.1:9000']
  syslog_facility: user
  chdir: /home/django/source/edc-pharma
  worker_exit: <function WorkerExit.worker_exit at 0x7facb73d0620>
  sendfile: None
  worker_tmp_dir: None
  user: 1004
  check_config: False
  logconfig: None
  enable_stdio_inheritance: False
  limit_request_fields: 100
  preload_app: False
  forwarded_allow_ips: ['127.0.0.1']
  pythonpath: None
  proxy_protocol: False
  reload: False
  default_proc_name: edc_pharma.wsgi
  suppress_ragged_eofs: True
  django_settings: None
  on_reload: <function OnReload.on_reload at 0x7facb73c6620>
  keepalive: 2
[2016-11-03 13:06:48 +0200] [10754] [INFO] Starting gunicorn 19.6.0
[2016-11-03 13:06:48 +0200] [10754] [DEBUG] Arbiter booted
[2016-11-03 13:06:48 +0200] [10754] [INFO] Listening at: http://127.0.0.1:9000 (10754)
[2016-11-03 13:06:48 +0200] [10754] [INFO] Using worker: sync
[2016-11-03 13:06:48 +0200] [10757] [INFO] Booting worker with pid: 10757
[2016-11-03 13:06:48 +0200] [10754] [DEBUG] 1 workers
[2016-11-03 13:06:58 +0200] [10757] [DEBUG] GET /
[2016-11-03 13:07:08 +0200] [10757] [ERROR] Error handling request /
Traceback (most recent call last):
  File "/home/django/.virtualenvs/edc-pharma/lib/python3.5/site-packages/django/contrib/sessions/backends/base.py", line 202, in _get_session
    return self._session_cache
AttributeError: 'SessionStore' object has no attribute '_session_cache'

During handling of the above exception, another exception occurred:

Traceback (most recent call last):
  File "/home/django/.virtualenvs/edc-pharma/lib/python3.5/site-packages/django/db/backends/utils.py", line 64, in execute
    return self.cursor.execute(sql, params)
  File "/home/django/.virtualenvs/edc-pharma/lib/python3.5/site-packages/django/db/backends/sqlite3/base.py", line 337, in execute
    return Database.Cursor.execute(self, query, params)
sqlite3.OperationalError: no such table: django_session

The above exception was the direct cause of the following exception:

Traceback (most recent call last):
  File "/home/django/.virtualenvs/edc-pharma/lib/python3.5/site-packages/django/core/handlers/exception.py", line 39, in inner
    response = get_response(request)
  File "/home/django/.virtualenvs/edc-pharma/lib/python3.5/site-packages/django/core/handlers/base.py", line 187, in _get_response
    response = self.process_exception_by_middleware(e, request)
  File "/home/django/.virtualenvs/edc-pharma/lib/python3.5/site-packages/django/core/handlers/base.py", line 185, in _get_response
    response = wrapped_callback(request, *callback_args, **callback_kwargs)
  File "/home/django/.virtualenvs/edc-pharma/lib/python3.5/site-packages/django/views/generic/base.py", line 68, in view
    return self.dispatch(request, *args, **kwargs)
  File "/home/django/.virtualenvs/edc-pharma/lib/python3.5/site-packages/django/utils/decorators.py", line 67, in _wrapper
    return bound_func(*args, **kwargs)
  File "/home/django/.virtualenvs/edc-pharma/lib/python3.5/site-packages/django/contrib/auth/decorators.py", line 22, in _wrapped_view
    if test_func(request.user):
  File "/home/django/.virtualenvs/edc-pharma/lib/python3.5/site-packages/django/contrib/auth/decorators.py", line 46, in <lambda>
    lambda u: u.is_authenticated,
  File "/home/django/.virtualenvs/edc-pharma/lib/python3.5/site-packages/django/utils/functional.py", line 234, in inner
    self._setup()
  File "/home/django/.virtualenvs/edc-pharma/lib/python3.5/site-packages/django/utils/functional.py", line 380, in _setup
    self._wrapped = self._setupfunc()
  File "/home/django/.virtualenvs/edc-pharma/lib/python3.5/site-packages/django/contrib/auth/middleware.py", line 24, in <lambda>
    request.user = SimpleLazyObject(lambda: get_user(request))
  File "/home/django/.virtualenvs/edc-pharma/lib/python3.5/site-packages/django/contrib/auth/middleware.py", line 12, in get_user
    request._cached_user = auth.get_user(request)
  File "/home/django/.virtualenvs/edc-pharma/lib/python3.5/site-packages/django/contrib/auth/__init__.py", line 180, in get_user
    user_id = _get_user_session_key(request)
  File "/home/django/.virtualenvs/edc-pharma/lib/python3.5/site-packages/django/contrib/auth/__init__.py", line 59, in _get_user_session_key
    return get_user_model()._meta.pk.to_python(request.session[SESSION_KEY])
  File "/home/django/.virtualenvs/edc-pharma/lib/python3.5/site-packages/django/contrib/sessions/backends/base.py", line 57, in __getitem__
    return self._session[key]
  File "/home/django/.virtualenvs/edc-pharma/lib/python3.5/site-packages/django/contrib/sessions/backends/base.py", line 207, in _get_session
    self._session_cache = self.load()
  File "/home/django/.virtualenvs/edc-pharma/lib/python3.5/site-packages/django/contrib/sessions/backends/db.py", line 35, in load
    expire_date__gt=timezone.now()
  File "/home/django/.virtualenvs/edc-pharma/lib/python3.5/site-packages/django/db/models/manager.py", line 85, in manager_method
    return getattr(self.get_queryset(), name)(*args, **kwargs)
  File "/home/django/.virtualenvs/edc-pharma/lib/python3.5/site-packages/django/db/models/query.py", line 379, in get
    num = len(clone)
  File "/home/django/.virtualenvs/edc-pharma/lib/python3.5/site-packages/django/db/models/query.py", line 238, in __len__
    self._fetch_all()
  File "/home/django/.virtualenvs/edc-pharma/lib/python3.5/site-packages/django/db/models/query.py", line 1087, in _fetch_all
    self._result_cache = list(self.iterator())
  File "/home/django/.virtualenvs/edc-pharma/lib/python3.5/site-packages/django/db/models/query.py", line 54, in __iter__
    results = compiler.execute_sql()
  File "/home/django/.virtualenvs/edc-pharma/lib/python3.5/site-packages/django/db/models/sql/compiler.py", line 835, in execute_sql
    cursor.execute(sql, params)
  File "/home/django/.virtualenvs/edc-pharma/lib/python3.5/site-packages/django/db/backends/utils.py", line 79, in execute
    return super(CursorDebugWrapper, self).execute(sql, params)
  File "/home/django/.virtualenvs/edc-pharma/lib/python3.5/site-packages/django/db/backends/utils.py", line 64, in execute
    return self.cursor.execute(sql, params)
  File "/home/django/.virtualenvs/edc-pharma/lib/python3.5/site-packages/django/db/utils.py", line 94, in __exit__
    six.reraise(dj_exc_type, dj_exc_value, traceback)
  File "/home/django/.virtualenvs/edc-pharma/lib/python3.5/site-packages/django/utils/six.py", line 685, in reraise
    raise value.with_traceback(tb)
  File "/home/django/.virtualenvs/edc-pharma/lib/python3.5/site-packages/django/db/backends/utils.py", line 64, in execute
    return self.cursor.execute(sql, params)
  File "/home/django/.virtualenvs/edc-pharma/lib/python3.5/site-packages/django/db/backends/sqlite3/base.py", line 337, in execute
    return Database.Cursor.execute(self, query, params)
django.db.utils.OperationalError: no such table: django_session

During handling of the above exception, another exception occurred:

Traceback (most recent call last):
  File "/home/django/.virtualenvs/edc-pharma/lib/python3.5/site-packages/django/contrib/sessions/backends/base.py", line 202, in _get_session
    return self._session_cache
AttributeError: 'SessionStore' object has no attribute '_session_cache'

During handling of the above exception, another exception occurred:

Traceback (most recent call last):
  File "/home/django/.virtualenvs/edc-pharma/lib/python3.5/site-packages/django/db/backends/utils.py", line 64, in execute
    return self.cursor.execute(sql, params)
  File "/home/django/.virtualenvs/edc-pharma/lib/python3.5/site-packages/django/db/backends/sqlite3/base.py", line 337, in execute
    return Database.Cursor.execute(self, query, params)
sqlite3.OperationalError: no such table: django_session

The above exception was the direct cause of the following exception:

Traceback (most recent call last):
  File "/home/django/.virtualenvs/edc-pharma/lib/python3.5/site-packages/django/core/handlers/exception.py", line 39, in inner
    response = get_response(request)
  File "/home/django/.virtualenvs/edc-pharma/lib/python3.5/site-packages/django/utils/deprecation.py", line 133, in __call__
    response = self.get_response(request)
  File "/home/django/.virtualenvs/edc-pharma/lib/python3.5/site-packages/django/core/handlers/exception.py", line 41, in inner
    response = response_for_exception(request, exc)
  File "/home/django/.virtualenvs/edc-pharma/lib/python3.5/site-packages/django/core/handlers/exception.py", line 86, in response_for_exception
    response = handle_uncaught_exception(request, get_resolver(get_urlconf()), sys.exc_info())
  File "/home/django/.virtualenvs/edc-pharma/lib/python3.5/site-packages/django/core/handlers/exception.py", line 128, in handle_uncaught_exception
    return debug.technical_500_response(request, *exc_info)
  File "/home/django/.virtualenvs/edc-pharma/lib/python3.5/site-packages/django/views/debug.py", line 84, in technical_500_response
    html = reporter.get_traceback_html()
  File "/home/django/.virtualenvs/edc-pharma/lib/python3.5/site-packages/django/views/debug.py", line 317, in get_traceback_html
    return t.render(c)
  File "/home/django/.virtualenvs/edc-pharma/lib/python3.5/site-packages/django/template/base.py", line 208, in render
    return self._render(context)
  File "/home/django/.virtualenvs/edc-pharma/lib/python3.5/site-packages/django/template/base.py", line 199, in _render
    return self.nodelist.render(context)
  File "/home/django/.virtualenvs/edc-pharma/lib/python3.5/site-packages/django/template/base.py", line 994, in render
    bit = node.render_annotated(context)
  File "/home/django/.virtualenvs/edc-pharma/lib/python3.5/site-packages/django/template/base.py", line 961, in render_annotated
    return self.render(context)
  File "/home/django/.virtualenvs/edc-pharma/lib/python3.5/site-packages/django/template/defaulttags.py", line 315, in render
    return nodelist.render(context)
  File "/home/django/.virtualenvs/edc-pharma/lib/python3.5/site-packages/django/template/base.py", line 994, in render
    bit = node.render_annotated(context)
  File "/home/django/.virtualenvs/edc-pharma/lib/python3.5/site-packages/django/template/base.py", line 961, in render_annotated
    return self.render(context)
  File "/home/django/.virtualenvs/edc-pharma/lib/python3.5/site-packages/django/template/defaulttags.py", line 314, in render
    if match:
  File "/home/django/.virtualenvs/edc-pharma/lib/python3.5/site-packages/django/utils/functional.py", line 234, in inner
    self._setup()
  File "/home/django/.virtualenvs/edc-pharma/lib/python3.5/site-packages/django/utils/functional.py", line 380, in _setup
    self._wrapped = self._setupfunc()
  File "/home/django/.virtualenvs/edc-pharma/lib/python3.5/site-packages/django/contrib/auth/middleware.py", line 24, in <lambda>
    request.user = SimpleLazyObject(lambda: get_user(request))
  File "/home/django/.virtualenvs/edc-pharma/lib/python3.5/site-packages/django/contrib/auth/middleware.py", line 12, in get_user
    request._cached_user = auth.get_user(request)
  File "/home/django/.virtualenvs/edc-pharma/lib/python3.5/site-packages/django/contrib/auth/__init__.py", line 180, in get_user
    user_id = _get_user_session_key(request)
  File "/home/django/.virtualenvs/edc-pharma/lib/python3.5/site-packages/django/contrib/auth/__init__.py", line 59, in _get_user_session_key
    return get_user_model()._meta.pk.to_python(request.session[SESSION_KEY])
  File "/home/django/.virtualenvs/edc-pharma/lib/python3.5/site-packages/django/contrib/sessions/backends/base.py", line 57, in __getitem__
    return self._session[key]
  File "/home/django/.virtualenvs/edc-pharma/lib/python3.5/site-packages/django/contrib/sessions/backends/base.py", line 207, in _get_session
    self._session_cache = self.load()
  File "/home/django/.virtualenvs/edc-pharma/lib/python3.5/site-packages/django/contrib/sessions/backends/db.py", line 35, in load
    expire_date__gt=timezone.now()
  File "/home/django/.virtualenvs/edc-pharma/lib/python3.5/site-packages/django/db/models/manager.py", line 85, in manager_method
    return getattr(self.get_queryset(), name)(*args, **kwargs)
  File "/home/django/.virtualenvs/edc-pharma/lib/python3.5/site-packages/django/db/models/query.py", line 379, in get
    num = len(clone)
  File "/home/django/.virtualenvs/edc-pharma/lib/python3.5/site-packages/django/db/models/query.py", line 238, in __len__
    self._fetch_all()
  File "/home/django/.virtualenvs/edc-pharma/lib/python3.5/site-packages/django/db/models/query.py", line 1087, in _fetch_all
    self._result_cache = list(self.iterator())
  File "/home/django/.virtualenvs/edc-pharma/lib/python3.5/site-packages/django/db/models/query.py", line 54, in __iter__
    results = compiler.execute_sql()
  File "/home/django/.virtualenvs/edc-pharma/lib/python3.5/site-packages/django/db/models/sql/compiler.py", line 835, in execute_sql
    cursor.execute(sql, params)
  File "/home/django/.virtualenvs/edc-pharma/lib/python3.5/site-packages/django/db/backends/utils.py", line 79, in execute
    return super(CursorDebugWrapper, self).execute(sql, params)
  File "/home/django/.virtualenvs/edc-pharma/lib/python3.5/site-packages/django/db/backends/utils.py", line 64, in execute
    return self.cursor.execute(sql, params)
  File "/home/django/.virtualenvs/edc-pharma/lib/python3.5/site-packages/django/db/utils.py", line 94, in __exit__
    six.reraise(dj_exc_type, dj_exc_value, traceback)
  File "/home/django/.virtualenvs/edc-pharma/lib/python3.5/site-packages/django/utils/six.py", line 685, in reraise
    raise value.with_traceback(tb)
  File "/home/django/.virtualenvs/edc-pharma/lib/python3.5/site-packages/django/db/backends/utils.py", line 64, in execute
    return self.cursor.execute(sql, params)
  File "/home/django/.virtualenvs/edc-pharma/lib/python3.5/site-packages/django/db/backends/sqlite3/base.py", line 337, in execute
    return Database.Cursor.execute(self, query, params)
django.db.utils.OperationalError: no such table: django_session

During handling of the above exception, another exception occurred:

Traceback (most recent call last):
  File "/home/django/.virtualenvs/edc-pharma/lib/python3.5/site-packages/django/contrib/sessions/backends/base.py", line 202, in _get_session
    return self._session_cache
AttributeError: 'SessionStore' object has no attribute '_session_cache'

During handling of the above exception, another exception occurred:

Traceback (most recent call last):
  File "/home/django/.virtualenvs/edc-pharma/lib/python3.5/site-packages/django/db/backends/utils.py", line 64, in execute
    return self.cursor.execute(sql, params)
  File "/home/django/.virtualenvs/edc-pharma/lib/python3.5/site-packages/django/db/backends/sqlite3/base.py", line 337, in execute
    return Database.Cursor.execute(self, query, params)
sqlite3.OperationalError: no such table: django_session

The above exception was the direct cause of the following exception:

Traceback (most recent call last):
  File "/home/django/.virtualenvs/edc-pharma/lib/python3.5/site-packages/django/core/handlers/exception.py", line 39, in inner
    response = get_response(request)
  File "/home/django/.virtualenvs/edc-pharma/lib/python3.5/site-packages/django/utils/deprecation.py", line 133, in __call__
    response = self.get_response(request)
  File "/home/django/.virtualenvs/edc-pharma/lib/python3.5/site-packages/django/core/handlers/exception.py", line 41, in inner
    response = response_for_exception(request, exc)
  File "/home/django/.virtualenvs/edc-pharma/lib/python3.5/site-packages/django/core/handlers/exception.py", line 86, in response_for_exception
    response = handle_uncaught_exception(request, get_resolver(get_urlconf()), sys.exc_info())
  File "/home/django/.virtualenvs/edc-pharma/lib/python3.5/site-packages/django/core/handlers/exception.py", line 128, in handle_uncaught_exception
    return debug.technical_500_response(request, *exc_info)
  File "/home/django/.virtualenvs/edc-pharma/lib/python3.5/site-packages/django/views/debug.py", line 84, in technical_500_response
    html = reporter.get_traceback_html()
  File "/home/django/.virtualenvs/edc-pharma/lib/python3.5/site-packages/django/views/debug.py", line 317, in get_traceback_html
    return t.render(c)
  File "/home/django/.virtualenvs/edc-pharma/lib/python3.5/site-packages/django/template/base.py", line 208, in render
    return self._render(context)
  File "/home/django/.virtualenvs/edc-pharma/lib/python3.5/site-packages/django/template/base.py", line 199, in _render
    return self.nodelist.render(context)
  File "/home/django/.virtualenvs/edc-pharma/lib/python3.5/site-packages/django/template/base.py", line 994, in render
    bit = node.render_annotated(context)
  File "/home/django/.virtualenvs/edc-pharma/lib/python3.5/site-packages/django/template/base.py", line 961, in render_annotated
    return self.render(context)
  File "/home/django/.virtualenvs/edc-pharma/lib/python3.5/site-packages/django/template/defaulttags.py", line 315, in render
    return nodelist.render(context)
  File "/home/django/.virtualenvs/edc-pharma/lib/python3.5/site-packages/django/template/base.py", line 994, in render
    bit = node.render_annotated(context)
  File "/home/django/.virtualenvs/edc-pharma/lib/python3.5/site-packages/django/template/base.py", line 961, in render_annotated
    return self.render(context)
  File "/home/django/.virtualenvs/edc-pharma/lib/python3.5/site-packages/django/template/defaulttags.py", line 314, in render
    if match:
  File "/home/django/.virtualenvs/edc-pharma/lib/python3.5/site-packages/django/utils/functional.py", line 234, in inner
    self._setup()
  File "/home/django/.virtualenvs/edc-pharma/lib/python3.5/site-packages/django/utils/functional.py", line 380, in _setup
    self._wrapped = self._setupfunc()
  File "/home/django/.virtualenvs/edc-pharma/lib/python3.5/site-packages/django/contrib/auth/middleware.py", line 24, in <lambda>
    request.user = SimpleLazyObject(lambda: get_user(request))
  File "/home/django/.virtualenvs/edc-pharma/lib/python3.5/site-packages/django/contrib/auth/middleware.py", line 12, in get_user
    request._cached_user = auth.get_user(request)
  File "/home/django/.virtualenvs/edc-pharma/lib/python3.5/site-packages/django/contrib/auth/__init__.py", line 180, in get_user
    user_id = _get_user_session_key(request)
  File "/home/django/.virtualenvs/edc-pharma/lib/python3.5/site-packages/django/contrib/auth/__init__.py", line 59, in _get_user_session_key
    return get_user_model()._meta.pk.to_python(request.session[SESSION_KEY])
  File "/home/django/.virtualenvs/edc-pharma/lib/python3.5/site-packages/django/contrib/sessions/backends/base.py", line 57, in __getitem__
    return self._session[key]
  File "/home/django/.virtualenvs/edc-pharma/lib/python3.5/site-packages/django/contrib/sessions/backends/base.py", line 207, in _get_session
    self._session_cache = self.load()
  File "/home/django/.virtualenvs/edc-pharma/lib/python3.5/site-packages/django/contrib/sessions/backends/db.py", line 35, in load
    expire_date__gt=timezone.now()
  File "/home/django/.virtualenvs/edc-pharma/lib/python3.5/site-packages/django/db/models/manager.py", line 85, in manager_method
    return getattr(self.get_queryset(), name)(*args, **kwargs)
  File "/home/django/.virtualenvs/edc-pharma/lib/python3.5/site-packages/django/db/models/query.py", line 379, in get
    num = len(clone)
  File "/home/django/.virtualenvs/edc-pharma/lib/python3.5/site-packages/django/db/models/query.py", line 238, in __len__
    self._fetch_all()
  File "/home/django/.virtualenvs/edc-pharma/lib/python3.5/site-packages/django/db/models/query.py", line 1087, in _fetch_all
    self._result_cache = list(self.iterator())
  File "/home/django/.virtualenvs/edc-pharma/lib/python3.5/site-packages/django/db/models/query.py", line 54, in __iter__
    results = compiler.execute_sql()
  File "/home/django/.virtualenvs/edc-pharma/lib/python3.5/site-packages/django/db/models/sql/compiler.py", line 835, in execute_sql
    cursor.execute(sql, params)
  File "/home/django/.virtualenvs/edc-pharma/lib/python3.5/site-packages/django/db/backends/utils.py", line 79, in execute
    return super(CursorDebugWrapper, self).execute(sql, params)
  File "/home/django/.virtualenvs/edc-pharma/lib/python3.5/site-packages/django/db/backends/utils.py", line 64, in execute
    return self.cursor.execute(sql, params)
  File "/home/django/.virtualenvs/edc-pharma/lib/python3.5/site-packages/django/db/utils.py", line 94, in __exit__
    six.reraise(dj_exc_type, dj_exc_value, traceback)
  File "/home/django/.virtualenvs/edc-pharma/lib/python3.5/site-packages/django/utils/six.py", line 685, in reraise
    raise value.with_traceback(tb)
  File "/home/django/.virtualenvs/edc-pharma/lib/python3.5/site-packages/django/db/backends/utils.py", line 64, in execute
    return self.cursor.execute(sql, params)
  File "/home/django/.virtualenvs/edc-pharma/lib/python3.5/site-packages/django/db/backends/sqlite3/base.py", line 337, in execute
    return Database.Cursor.execute(self, query, params)
django.db.utils.OperationalError: no such table: django_session

During handling of the above exception, another exception occurred:

Traceback (most recent call last):
  File "/home/django/.virtualenvs/edc-pharma/lib/python3.5/site-packages/django/contrib/sessions/backends/base.py", line 202, in _get_session
    return self._session_cache
AttributeError: 'SessionStore' object has no attribute '_session_cache'

During handling of the above exception, another exception occurred:

Traceback (most recent call last):
  File "/home/django/.virtualenvs/edc-pharma/lib/python3.5/site-packages/django/db/backends/utils.py", line 64, in execute
    return self.cursor.execute(sql, params)
  File "/home/django/.virtualenvs/edc-pharma/lib/python3.5/site-packages/django/db/backends/sqlite3/base.py", line 337, in execute
    return Database.Cursor.execute(self, query, params)
sqlite3.OperationalError: no such table: django_session

The above exception was the direct cause of the following exception:

Traceback (most recent call last):
  File "/home/django/.virtualenvs/edc-pharma/lib/python3.5/site-packages/django/core/handlers/exception.py", line 39, in inner
    response = get_response(request)
  File "/home/django/.virtualenvs/edc-pharma/lib/python3.5/site-packages/django/utils/deprecation.py", line 133, in __call__
    response = self.get_response(request)
  File "/home/django/.virtualenvs/edc-pharma/lib/python3.5/site-packages/django/core/handlers/exception.py", line 41, in inner
    response = response_for_exception(request, exc)
  File "/home/django/.virtualenvs/edc-pharma/lib/python3.5/site-packages/django/core/handlers/exception.py", line 86, in response_for_exception
    response = handle_uncaught_exception(request, get_resolver(get_urlconf()), sys.exc_info())
  File "/home/django/.virtualenvs/edc-pharma/lib/python3.5/site-packages/django/core/handlers/exception.py", line 128, in handle_uncaught_exception
    return debug.technical_500_response(request, *exc_info)
  File "/home/django/.virtualenvs/edc-pharma/lib/python3.5/site-packages/django/views/debug.py", line 84, in technical_500_response
    html = reporter.get_traceback_html()
  File "/home/django/.virtualenvs/edc-pharma/lib/python3.5/site-packages/django/views/debug.py", line 317, in get_traceback_html
    return t.render(c)
  File "/home/django/.virtualenvs/edc-pharma/lib/python3.5/site-packages/django/template/base.py", line 208, in render
    return self._render(context)
  File "/home/django/.virtualenvs/edc-pharma/lib/python3.5/site-packages/django/template/base.py", line 199, in _render
    return self.nodelist.render(context)
  File "/home/django/.virtualenvs/edc-pharma/lib/python3.5/site-packages/django/template/base.py", line 994, in render
    bit = node.render_annotated(context)
  File "/home/django/.virtualenvs/edc-pharma/lib/python3.5/site-packages/django/template/base.py", line 961, in render_annotated
    return self.render(context)
  File "/home/django/.virtualenvs/edc-pharma/lib/python3.5/site-packages/django/template/defaulttags.py", line 315, in render
    return nodelist.render(context)
  File "/home/django/.virtualenvs/edc-pharma/lib/python3.5/site-packages/django/template/base.py", line 994, in render
    bit = node.render_annotated(context)
  File "/home/django/.virtualenvs/edc-pharma/lib/python3.5/site-packages/django/template/base.py", line 961, in render_annotated
    return self.render(context)
  File "/home/django/.virtualenvs/edc-pharma/lib/python3.5/site-packages/django/template/defaulttags.py", line 314, in render
    if match:
  File "/home/django/.virtualenvs/edc-pharma/lib/python3.5/site-packages/django/utils/functional.py", line 234, in inner
    self._setup()
  File "/home/django/.virtualenvs/edc-pharma/lib/python3.5/site-packages/django/utils/functional.py", line 380, in _setup
    self._wrapped = self._setupfunc()
  File "/home/django/.virtualenvs/edc-pharma/lib/python3.5/site-packages/django/contrib/auth/middleware.py", line 24, in <lambda>
    request.user = SimpleLazyObject(lambda: get_user(request))
  File "/home/django/.virtualenvs/edc-pharma/lib/python3.5/site-packages/django/contrib/auth/middleware.py", line 12, in get_user
    request._cached_user = auth.get_user(request)
  File "/home/django/.virtualenvs/edc-pharma/lib/python3.5/site-packages/django/contrib/auth/__init__.py", line 180, in get_user
    user_id = _get_user_session_key(request)
  File "/home/django/.virtualenvs/edc-pharma/lib/python3.5/site-packages/django/contrib/auth/__init__.py", line 59, in _get_user_session_key
    return get_user_model()._meta.pk.to_python(request.session[SESSION_KEY])
  File "/home/django/.virtualenvs/edc-pharma/lib/python3.5/site-packages/django/contrib/sessions/backends/base.py", line 57, in __getitem__
    return self._session[key]
  File "/home/django/.virtualenvs/edc-pharma/lib/python3.5/site-packages/django/contrib/sessions/backends/base.py", line 207, in _get_session
    self._session_cache = self.load()
  File "/home/django/.virtualenvs/edc-pharma/lib/python3.5/site-packages/django/contrib/sessions/backends/db.py", line 35, in load
    expire_date__gt=timezone.now()
  File "/home/django/.virtualenvs/edc-pharma/lib/python3.5/site-packages/django/db/models/manager.py", line 85, in manager_method
    return getattr(self.get_queryset(), name)(*args, **kwargs)
  File "/home/django/.virtualenvs/edc-pharma/lib/python3.5/site-packages/django/db/models/query.py", line 379, in get
    num = len(clone)
  File "/home/django/.virtualenvs/edc-pharma/lib/python3.5/site-packages/django/db/models/query.py", line 238, in __len__
    self._fetch_all()
  File "/home/django/.virtualenvs/edc-pharma/lib/python3.5/site-packages/django/db/models/query.py", line 1087, in _fetch_all
    self._result_cache = list(self.iterator())
  File "/home/django/.virtualenvs/edc-pharma/lib/python3.5/site-packages/django/db/models/query.py", line 54, in __iter__
    results = compiler.execute_sql()
  File "/home/django/.virtualenvs/edc-pharma/lib/python3.5/site-packages/django/db/models/sql/compiler.py", line 835, in execute_sql
    cursor.execute(sql, params)
  File "/home/django/.virtualenvs/edc-pharma/lib/python3.5/site-packages/django/db/backends/utils.py", line 79, in execute
    return super(CursorDebugWrapper, self).execute(sql, params)
  File "/home/django/.virtualenvs/edc-pharma/lib/python3.5/site-packages/django/db/backends/utils.py", line 64, in execute
    return self.cursor.execute(sql, params)
  File "/home/django/.virtualenvs/edc-pharma/lib/python3.5/site-packages/django/db/utils.py", line 94, in __exit__
    six.reraise(dj_exc_type, dj_exc_value, traceback)
  File "/home/django/.virtualenvs/edc-pharma/lib/python3.5/site-packages/django/utils/six.py", line 685, in reraise
    raise value.with_traceback(tb)
  File "/home/django/.virtualenvs/edc-pharma/lib/python3.5/site-packages/django/db/backends/utils.py", line 64, in execute
    return self.cursor.execute(sql, params)
  File "/home/django/.virtualenvs/edc-pharma/lib/python3.5/site-packages/django/db/backends/sqlite3/base.py", line 337, in execute
    return Database.Cursor.execute(self, query, params)
django.db.utils.OperationalError: no such table: django_session

During handling of the above exception, another exception occurred:

Traceback (most recent call last):
  File "/home/django/.virtualenvs/edc-pharma/lib/python3.5/site-packages/django/contrib/sessions/backends/base.py", line 202, in _get_session
    return self._session_cache
AttributeError: 'SessionStore' object has no attribute '_session_cache'

During handling of the above exception, another exception occurred:

Traceback (most recent call last):
  File "/home/django/.virtualenvs/edc-pharma/lib/python3.5/site-packages/django/db/backends/utils.py", line 64, in execute
    return self.cursor.execute(sql, params)
  File "/home/django/.virtualenvs/edc-pharma/lib/python3.5/site-packages/django/db/backends/sqlite3/base.py", line 337, in execute
    return Database.Cursor.execute(self, query, params)
sqlite3.OperationalError: no such table: django_session

The above exception was the direct cause of the following exception:

Traceback (most recent call last):
  File "/home/django/.virtualenvs/edc-pharma/lib/python3.5/site-packages/django/core/handlers/exception.py", line 39, in inner
    response = get_response(request)
  File "/home/django/.virtualenvs/edc-pharma/lib/python3.5/site-packages/django/utils/deprecation.py", line 133, in __call__
    response = self.get_response(request)
  File "/home/django/.virtualenvs/edc-pharma/lib/python3.5/site-packages/django/core/handlers/exception.py", line 41, in inner
    response = response_for_exception(request, exc)
  File "/home/django/.virtualenvs/edc-pharma/lib/python3.5/site-packages/django/core/handlers/exception.py", line 86, in response_for_exception
    response = handle_uncaught_exception(request, get_resolver(get_urlconf()), sys.exc_info())
  File "/home/django/.virtualenvs/edc-pharma/lib/python3.5/site-packages/django/core/handlers/exception.py", line 128, in handle_uncaught_exception
    return debug.technical_500_response(request, *exc_info)
  File "/home/django/.virtualenvs/edc-pharma/lib/python3.5/site-packages/django/views/debug.py", line 84, in technical_500_response
    html = reporter.get_traceback_html()
  File "/home/django/.virtualenvs/edc-pharma/lib/python3.5/site-packages/django/views/debug.py", line 317, in get_traceback_html
    return t.render(c)
  File "/home/django/.virtualenvs/edc-pharma/lib/python3.5/site-packages/django/template/base.py", line 208, in render
    return self._render(context)
  File "/home/django/.virtualenvs/edc-pharma/lib/python3.5/site-packages/django/template/base.py", line 199, in _render
    return self.nodelist.render(context)
  File "/home/django/.virtualenvs/edc-pharma/lib/python3.5/site-packages/django/template/base.py", line 994, in render
    bit = node.render_annotated(context)
  File "/home/django/.virtualenvs/edc-pharma/lib/python3.5/site-packages/django/template/base.py", line 961, in render_annotated
    return self.render(context)
  File "/home/django/.virtualenvs/edc-pharma/lib/python3.5/site-packages/django/template/defaulttags.py", line 315, in render
    return nodelist.render(context)
  File "/home/django/.virtualenvs/edc-pharma/lib/python3.5/site-packages/django/template/base.py", line 994, in render
    bit = node.render_annotated(context)
  File "/home/django/.virtualenvs/edc-pharma/lib/python3.5/site-packages/django/template/base.py", line 961, in render_annotated
    return self.render(context)
  File "/home/django/.virtualenvs/edc-pharma/lib/python3.5/site-packages/django/template/defaulttags.py", line 314, in render
    if match:
  File "/home/django/.virtualenvs/edc-pharma/lib/python3.5/site-packages/django/utils/functional.py", line 234, in inner
    self._setup()
  File "/home/django/.virtualenvs/edc-pharma/lib/python3.5/site-packages/django/utils/functional.py", line 380, in _setup
    self._wrapped = self._setupfunc()
  File "/home/django/.virtualenvs/edc-pharma/lib/python3.5/site-packages/django/contrib/auth/middleware.py", line 24, in <lambda>
    request.user = SimpleLazyObject(lambda: get_user(request))
  File "/home/django/.virtualenvs/edc-pharma/lib/python3.5/site-packages/django/contrib/auth/middleware.py", line 12, in get_user
    request._cached_user = auth.get_user(request)
  File "/home/django/.virtualenvs/edc-pharma/lib/python3.5/site-packages/django/contrib/auth/__init__.py", line 180, in get_user
    user_id = _get_user_session_key(request)
  File "/home/django/.virtualenvs/edc-pharma/lib/python3.5/site-packages/django/contrib/auth/__init__.py", line 59, in _get_user_session_key
    return get_user_model()._meta.pk.to_python(request.session[SESSION_KEY])
  File "/home/django/.virtualenvs/edc-pharma/lib/python3.5/site-packages/django/contrib/sessions/backends/base.py", line 57, in __getitem__
    return self._session[key]
  File "/home/django/.virtualenvs/edc-pharma/lib/python3.5/site-packages/django/contrib/sessions/backends/base.py", line 207, in _get_session
    self._session_cache = self.load()
  File "/home/django/.virtualenvs/edc-pharma/lib/python3.5/site-packages/django/contrib/sessions/backends/db.py", line 35, in load
    expire_date__gt=timezone.now()
  File "/home/django/.virtualenvs/edc-pharma/lib/python3.5/site-packages/django/db/models/manager.py", line 85, in manager_method
    return getattr(self.get_queryset(), name)(*args, **kwargs)
  File "/home/django/.virtualenvs/edc-pharma/lib/python3.5/site-packages/django/db/models/query.py", line 379, in get
    num = len(clone)
  File "/home/django/.virtualenvs/edc-pharma/lib/python3.5/site-packages/django/db/models/query.py", line 238, in __len__
    self._fetch_all()
  File "/home/django/.virtualenvs/edc-pharma/lib/python3.5/site-packages/django/db/models/query.py", line 1087, in _fetch_all
    self._result_cache = list(self.iterator())
  File "/home/django/.virtualenvs/edc-pharma/lib/python3.5/site-packages/django/db/models/query.py", line 54, in __iter__
    results = compiler.execute_sql()
  File "/home/django/.virtualenvs/edc-pharma/lib/python3.5/site-packages/django/db/models/sql/compiler.py", line 835, in execute_sql
    cursor.execute(sql, params)
  File "/home/django/.virtualenvs/edc-pharma/lib/python3.5/site-packages/django/db/backends/utils.py", line 79, in execute
    return super(CursorDebugWrapper, self).execute(sql, params)
  File "/home/django/.virtualenvs/edc-pharma/lib/python3.5/site-packages/django/db/backends/utils.py", line 64, in execute
    return self.cursor.execute(sql, params)
  File "/home/django/.virtualenvs/edc-pharma/lib/python3.5/site-packages/django/db/utils.py", line 94, in __exit__
    six.reraise(dj_exc_type, dj_exc_value, traceback)
  File "/home/django/.virtualenvs/edc-pharma/lib/python3.5/site-packages/django/utils/six.py", line 685, in reraise
    raise value.with_traceback(tb)
  File "/home/django/.virtualenvs/edc-pharma/lib/python3.5/site-packages/django/db/backends/utils.py", line 64, in execute
    return self.cursor.execute(sql, params)
  File "/home/django/.virtualenvs/edc-pharma/lib/python3.5/site-packages/django/db/backends/sqlite3/base.py", line 337, in execute
    return Database.Cursor.execute(self, query, params)
django.db.utils.OperationalError: no such table: django_session

During handling of the above exception, another exception occurred:

Traceback (most recent call last):
  File "/home/django/.virtualenvs/edc-pharma/lib/python3.5/site-packages/django/contrib/sessions/backends/base.py", line 202, in _get_session
    return self._session_cache
AttributeError: 'SessionStore' object has no attribute '_session_cache'

During handling of the above exception, another exception occurred:

Traceback (most recent call last):
  File "/home/django/.virtualenvs/edc-pharma/lib/python3.5/site-packages/django/db/backends/utils.py", line 64, in execute
    return self.cursor.execute(sql, params)
  File "/home/django/.virtualenvs/edc-pharma/lib/python3.5/site-packages/django/db/backends/sqlite3/base.py", line 337, in execute
    return Database.Cursor.execute(self, query, params)
sqlite3.OperationalError: no such table: django_session

The above exception was the direct cause of the following exception:

Traceback (most recent call last):
  File "/home/django/.virtualenvs/edc-pharma/lib/python3.5/site-packages/django/core/handlers/exception.py", line 39, in inner
    response = get_response(request)
  File "/home/django/.virtualenvs/edc-pharma/lib/python3.5/site-packages/django/utils/deprecation.py", line 133, in __call__
    response = self.get_response(request)
  File "/home/django/.virtualenvs/edc-pharma/lib/python3.5/site-packages/django/core/handlers/exception.py", line 41, in inner
    response = response_for_exception(request, exc)
  File "/home/django/.virtualenvs/edc-pharma/lib/python3.5/site-packages/django/core/handlers/exception.py", line 86, in response_for_exception
    response = handle_uncaught_exception(request, get_resolver(get_urlconf()), sys.exc_info())
  File "/home/django/.virtualenvs/edc-pharma/lib/python3.5/site-packages/django/core/handlers/exception.py", line 128, in handle_uncaught_exception
    return debug.technical_500_response(request, *exc_info)
  File "/home/django/.virtualenvs/edc-pharma/lib/python3.5/site-packages/django/views/debug.py", line 84, in technical_500_response
    html = reporter.get_traceback_html()
  File "/home/django/.virtualenvs/edc-pharma/lib/python3.5/site-packages/django/views/debug.py", line 317, in get_traceback_html
    return t.render(c)
  File "/home/django/.virtualenvs/edc-pharma/lib/python3.5/site-packages/django/template/base.py", line 208, in render
    return self._render(context)
  File "/home/django/.virtualenvs/edc-pharma/lib/python3.5/site-packages/django/template/base.py", line 199, in _render
    return self.nodelist.render(context)
  File "/home/django/.virtualenvs/edc-pharma/lib/python3.5/site-packages/django/template/base.py", line 994, in render
    bit = node.render_annotated(context)
  File "/home/django/.virtualenvs/edc-pharma/lib/python3.5/site-packages/django/template/base.py", line 961, in render_annotated
    return self.render(context)
  File "/home/django/.virtualenvs/edc-pharma/lib/python3.5/site-packages/django/template/defaulttags.py", line 315, in render
    return nodelist.render(context)
  File "/home/django/.virtualenvs/edc-pharma/lib/python3.5/site-packages/django/template/base.py", line 994, in render
    bit = node.render_annotated(context)
  File "/home/django/.virtualenvs/edc-pharma/lib/python3.5/site-packages/django/template/base.py", line 961, in render_annotated
    return self.render(context)
  File "/home/django/.virtualenvs/edc-pharma/lib/python3.5/site-packages/django/template/defaulttags.py", line 314, in render
    if match:
  File "/home/django/.virtualenvs/edc-pharma/lib/python3.5/site-packages/django/utils/functional.py", line 234, in inner
    self._setup()
  File "/home/django/.virtualenvs/edc-pharma/lib/python3.5/site-packages/django/utils/functional.py", line 380, in _setup
    self._wrapped = self._setupfunc()
  File "/home/django/.virtualenvs/edc-pharma/lib/python3.5/site-packages/django/contrib/auth/middleware.py", line 24, in <lambda>
    request.user = SimpleLazyObject(lambda: get_user(request))
  File "/home/django/.virtualenvs/edc-pharma/lib/python3.5/site-packages/django/contrib/auth/middleware.py", line 12, in get_user
    request._cached_user = auth.get_user(request)
  File "/home/django/.virtualenvs/edc-pharma/lib/python3.5/site-packages/django/contrib/auth/__init__.py", line 180, in get_user
    user_id = _get_user_session_key(request)
  File "/home/django/.virtualenvs/edc-pharma/lib/python3.5/site-packages/django/contrib/auth/__init__.py", line 59, in _get_user_session_key
    return get_user_model()._meta.pk.to_python(request.session[SESSION_KEY])
  File "/home/django/.virtualenvs/edc-pharma/lib/python3.5/site-packages/django/contrib/sessions/backends/base.py", line 57, in __getitem__
    return self._session[key]
  File "/home/django/.virtualenvs/edc-pharma/lib/python3.5/site-packages/django/contrib/sessions/backends/base.py", line 207, in _get_session
    self._session_cache = self.load()
  File "/home/django/.virtualenvs/edc-pharma/lib/python3.5/site-packages/django/contrib/sessions/backends/db.py", line 35, in load
    expire_date__gt=timezone.now()
  File "/home/django/.virtualenvs/edc-pharma/lib/python3.5/site-packages/django/db/models/manager.py", line 85, in manager_method
    return getattr(self.get_queryset(), name)(*args, **kwargs)
  File "/home/django/.virtualenvs/edc-pharma/lib/python3.5/site-packages/django/db/models/query.py", line 379, in get
    num = len(clone)
  File "/home/django/.virtualenvs/edc-pharma/lib/python3.5/site-packages/django/db/models/query.py", line 238, in __len__
    self._fetch_all()
  File "/home/django/.virtualenvs/edc-pharma/lib/python3.5/site-packages/django/db/models/query.py", line 1087, in _fetch_all
    self._result_cache = list(self.iterator())
  File "/home/django/.virtualenvs/edc-pharma/lib/python3.5/site-packages/django/db/models/query.py", line 54, in __iter__
    results = compiler.execute_sql()
  File "/home/django/.virtualenvs/edc-pharma/lib/python3.5/site-packages/django/db/models/sql/compiler.py", line 835, in execute_sql
    cursor.execute(sql, params)
  File "/home/django/.virtualenvs/edc-pharma/lib/python3.5/site-packages/django/db/backends/utils.py", line 79, in execute
    return super(CursorDebugWrapper, self).execute(sql, params)
  File "/home/django/.virtualenvs/edc-pharma/lib/python3.5/site-packages/django/db/backends/utils.py", line 64, in execute
    return self.cursor.execute(sql, params)
  File "/home/django/.virtualenvs/edc-pharma/lib/python3.5/site-packages/django/db/utils.py", line 94, in __exit__
    six.reraise(dj_exc_type, dj_exc_value, traceback)
  File "/home/django/.virtualenvs/edc-pharma/lib/python3.5/site-packages/django/utils/six.py", line 685, in reraise
    raise value.with_traceback(tb)
  File "/home/django/.virtualenvs/edc-pharma/lib/python3.5/site-packages/django/db/backends/utils.py", line 64, in execute
    return self.cursor.execute(sql, params)
  File "/home/django/.virtualenvs/edc-pharma/lib/python3.5/site-packages/django/db/backends/sqlite3/base.py", line 337, in execute
    return Database.Cursor.execute(self, query, params)
django.db.utils.OperationalError: no such table: django_session

During handling of the above exception, another exception occurred:

Traceback (most recent call last):
  File "/home/django/.virtualenvs/edc-pharma/lib/python3.5/site-packages/django/contrib/sessions/backends/base.py", line 202, in _get_session
    return self._session_cache
AttributeError: 'SessionStore' object has no attribute '_session_cache'

During handling of the above exception, another exception occurred:

Traceback (most recent call last):
  File "/home/django/.virtualenvs/edc-pharma/lib/python3.5/site-packages/django/db/backends/utils.py", line 64, in execute
    return self.cursor.execute(sql, params)
  File "/home/django/.virtualenvs/edc-pharma/lib/python3.5/site-packages/django/db/backends/sqlite3/base.py", line 337, in execute
    return Database.Cursor.execute(self, query, params)
sqlite3.OperationalError: no such table: django_session

The above exception was the direct cause of the following exception:

Traceback (most recent call last):
  File "/home/django/.virtualenvs/edc-pharma/lib/python3.5/site-packages/django/core/handlers/exception.py", line 39, in inner
    response = get_response(request)
  File "/home/django/.virtualenvs/edc-pharma/lib/python3.5/site-packages/django/utils/deprecation.py", line 133, in __call__
    response = self.get_response(request)
  File "/home/django/.virtualenvs/edc-pharma/lib/python3.5/site-packages/django/core/handlers/exception.py", line 41, in inner
    response = response_for_exception(request, exc)
  File "/home/django/.virtualenvs/edc-pharma/lib/python3.5/site-packages/django/core/handlers/exception.py", line 86, in response_for_exception
    response = handle_uncaught_exception(request, get_resolver(get_urlconf()), sys.exc_info())
  File "/home/django/.virtualenvs/edc-pharma/lib/python3.5/site-packages/django/core/handlers/exception.py", line 128, in handle_uncaught_exception
    return debug.technical_500_response(request, *exc_info)
  File "/home/django/.virtualenvs/edc-pharma/lib/python3.5/site-packages/django/views/debug.py", line 84, in technical_500_response
    html = reporter.get_traceback_html()
  File "/home/django/.virtualenvs/edc-pharma/lib/python3.5/site-packages/django/views/debug.py", line 317, in get_traceback_html
    return t.render(c)
  File "/home/django/.virtualenvs/edc-pharma/lib/python3.5/site-packages/django/template/base.py", line 208, in render
    return self._render(context)
  File "/home/django/.virtualenvs/edc-pharma/lib/python3.5/site-packages/django/template/base.py", line 199, in _render
    return self.nodelist.render(context)
  File "/home/django/.virtualenvs/edc-pharma/lib/python3.5/site-packages/django/template/base.py", line 994, in render
    bit = node.render_annotated(context)
  File "/home/django/.virtualenvs/edc-pharma/lib/python3.5/site-packages/django/template/base.py", line 961, in render_annotated
    return self.render(context)
  File "/home/django/.virtualenvs/edc-pharma/lib/python3.5/site-packages/django/template/defaulttags.py", line 315, in render
    return nodelist.render(context)
  File "/home/django/.virtualenvs/edc-pharma/lib/python3.5/site-packages/django/template/base.py", line 994, in render
    bit = node.render_annotated(context)
  File "/home/django/.virtualenvs/edc-pharma/lib/python3.5/site-packages/django/template/base.py", line 961, in render_annotated
    return self.render(context)
  File "/home/django/.virtualenvs/edc-pharma/lib/python3.5/site-packages/django/template/defaulttags.py", line 314, in render
    if match:
  File "/home/django/.virtualenvs/edc-pharma/lib/python3.5/site-packages/django/utils/functional.py", line 234, in inner
    self._setup()
  File "/home/django/.virtualenvs/edc-pharma/lib/python3.5/site-packages/django/utils/functional.py", line 380, in _setup
    self._wrapped = self._setupfunc()
  File "/home/django/.virtualenvs/edc-pharma/lib/python3.5/site-packages/django/contrib/auth/middleware.py", line 24, in <lambda>
    request.user = SimpleLazyObject(lambda: get_user(request))
  File "/home/django/.virtualenvs/edc-pharma/lib/python3.5/site-packages/django/contrib/auth/middleware.py", line 12, in get_user
    request._cached_user = auth.get_user(request)
  File "/home/django/.virtualenvs/edc-pharma/lib/python3.5/site-packages/django/contrib/auth/__init__.py", line 180, in get_user
    user_id = _get_user_session_key(request)
  File "/home/django/.virtualenvs/edc-pharma/lib/python3.5/site-packages/django/contrib/auth/__init__.py", line 59, in _get_user_session_key
    return get_user_model()._meta.pk.to_python(request.session[SESSION_KEY])
  File "/home/django/.virtualenvs/edc-pharma/lib/python3.5/site-packages/django/contrib/sessions/backends/base.py", line 57, in __getitem__
    return self._session[key]
  File "/home/django/.virtualenvs/edc-pharma/lib/python3.5/site-packages/django/contrib/sessions/backends/base.py", line 207, in _get_session
    self._session_cache = self.load()
  File "/home/django/.virtualenvs/edc-pharma/lib/python3.5/site-packages/django/contrib/sessions/backends/db.py", line 35, in load
    expire_date__gt=timezone.now()
  File "/home/django/.virtualenvs/edc-pharma/lib/python3.5/site-packages/django/db/models/manager.py", line 85, in manager_method
    return getattr(self.get_queryset(), name)(*args, **kwargs)
  File "/home/django/.virtualenvs/edc-pharma/lib/python3.5/site-packages/django/db/models/query.py", line 379, in get
    num = len(clone)
  File "/home/django/.virtualenvs/edc-pharma/lib/python3.5/site-packages/django/db/models/query.py", line 238, in __len__
    self._fetch_all()
  File "/home/django/.virtualenvs/edc-pharma/lib/python3.5/site-packages/django/db/models/query.py", line 1087, in _fetch_all
    self._result_cache = list(self.iterator())
  File "/home/django/.virtualenvs/edc-pharma/lib/python3.5/site-packages/django/db/models/query.py", line 54, in __iter__
    results = compiler.execute_sql()
  File "/home/django/.virtualenvs/edc-pharma/lib/python3.5/site-packages/django/db/models/sql/compiler.py", line 835, in execute_sql
    cursor.execute(sql, params)
  File "/home/django/.virtualenvs/edc-pharma/lib/python3.5/site-packages/django/db/backends/utils.py", line 79, in execute
    return super(CursorDebugWrapper, self).execute(sql, params)
  File "/home/django/.virtualenvs/edc-pharma/lib/python3.5/site-packages/django/db/backends/utils.py", line 64, in execute
    return self.cursor.execute(sql, params)
  File "/home/django/.virtualenvs/edc-pharma/lib/python3.5/site-packages/django/db/utils.py", line 94, in __exit__
    six.reraise(dj_exc_type, dj_exc_value, traceback)
  File "/home/django/.virtualenvs/edc-pharma/lib/python3.5/site-packages/django/utils/six.py", line 685, in reraise
    raise value.with_traceback(tb)
  File "/home/django/.virtualenvs/edc-pharma/lib/python3.5/site-packages/django/db/backends/utils.py", line 64, in execute
    return self.cursor.execute(sql, params)
  File "/home/django/.virtualenvs/edc-pharma/lib/python3.5/site-packages/django/db/backends/sqlite3/base.py", line 337, in execute
    return Database.Cursor.execute(self, query, params)
django.db.utils.OperationalError: no such table: django_session

During handling of the above exception, another exception occurred:

Traceback (most recent call last):
  File "/home/django/.virtualenvs/edc-pharma/lib/python3.5/site-packages/django/contrib/sessions/backends/base.py", line 202, in _get_session
    return self._session_cache
AttributeError: 'SessionStore' object has no attribute '_session_cache'

During handling of the above exception, another exception occurred:

Traceback (most recent call last):
  File "/home/django/.virtualenvs/edc-pharma/lib/python3.5/site-packages/django/db/backends/utils.py", line 64, in execute
    return self.cursor.execute(sql, params)
  File "/home/django/.virtualenvs/edc-pharma/lib/python3.5/site-packages/django/db/backends/sqlite3/base.py", line 337, in execute
    return Database.Cursor.execute(self, query, params)
sqlite3.OperationalError: no such table: django_session

The above exception was the direct cause of the following exception:

Traceback (most recent call last):
  File "/home/django/.virtualenvs/edc-pharma/lib/python3.5/site-packages/django/core/handlers/exception.py", line 39, in inner
    response = get_response(request)
  File "/home/django/.virtualenvs/edc-pharma/lib/python3.5/site-packages/django/utils/deprecation.py", line 133, in __call__
    response = self.get_response(request)
  File "/home/django/.virtualenvs/edc-pharma/lib/python3.5/site-packages/django/core/handlers/exception.py", line 41, in inner
    response = response_for_exception(request, exc)
  File "/home/django/.virtualenvs/edc-pharma/lib/python3.5/site-packages/django/core/handlers/exception.py", line 86, in response_for_exception
    response = handle_uncaught_exception(request, get_resolver(get_urlconf()), sys.exc_info())
  File "/home/django/.virtualenvs/edc-pharma/lib/python3.5/site-packages/django/core/handlers/exception.py", line 128, in handle_uncaught_exception
    return debug.technical_500_response(request, *exc_info)
  File "/home/django/.virtualenvs/edc-pharma/lib/python3.5/site-packages/django/views/debug.py", line 84, in technical_500_response
    html = reporter.get_traceback_html()
  File "/home/django/.virtualenvs/edc-pharma/lib/python3.5/site-packages/django/views/debug.py", line 317, in get_traceback_html
    return t.render(c)
  File "/home/django/.virtualenvs/edc-pharma/lib/python3.5/site-packages/django/template/base.py", line 208, in render
    return self._render(context)
  File "/home/django/.virtualenvs/edc-pharma/lib/python3.5/site-packages/django/template/base.py", line 199, in _render
    return self.nodelist.render(context)
  File "/home/django/.virtualenvs/edc-pharma/lib/python3.5/site-packages/django/template/base.py", line 994, in render
    bit = node.render_annotated(context)
  File "/home/django/.virtualenvs/edc-pharma/lib/python3.5/site-packages/django/template/base.py", line 961, in render_annotated
    return self.render(context)
  File "/home/django/.virtualenvs/edc-pharma/lib/python3.5/site-packages/django/template/defaulttags.py", line 315, in render
    return nodelist.render(context)
  File "/home/django/.virtualenvs/edc-pharma/lib/python3.5/site-packages/django/template/base.py", line 994, in render
    bit = node.render_annotated(context)
  File "/home/django/.virtualenvs/edc-pharma/lib/python3.5/site-packages/django/template/base.py", line 961, in render_annotated
    return self.render(context)
  File "/home/django/.virtualenvs/edc-pharma/lib/python3.5/site-packages/django/template/defaulttags.py", line 314, in render
    if match:
  File "/home/django/.virtualenvs/edc-pharma/lib/python3.5/site-packages/django/utils/functional.py", line 234, in inner
    self._setup()
  File "/home/django/.virtualenvs/edc-pharma/lib/python3.5/site-packages/django/utils/functional.py", line 380, in _setup
    self._wrapped = self._setupfunc()
  File "/home/django/.virtualenvs/edc-pharma/lib/python3.5/site-packages/django/contrib/auth/middleware.py", line 24, in <lambda>
    request.user = SimpleLazyObject(lambda: get_user(request))
  File "/home/django/.virtualenvs/edc-pharma/lib/python3.5/site-packages/django/contrib/auth/middleware.py", line 12, in get_user
    request._cached_user = auth.get_user(request)
  File "/home/django/.virtualenvs/edc-pharma/lib/python3.5/site-packages/django/contrib/auth/__init__.py", line 180, in get_user
    user_id = _get_user_session_key(request)
  File "/home/django/.virtualenvs/edc-pharma/lib/python3.5/site-packages/django/contrib/auth/__init__.py", line 59, in _get_user_session_key
    return get_user_model()._meta.pk.to_python(request.session[SESSION_KEY])
  File "/home/django/.virtualenvs/edc-pharma/lib/python3.5/site-packages/django/contrib/sessions/backends/base.py", line 57, in __getitem__
    return self._session[key]
  File "/home/django/.virtualenvs/edc-pharma/lib/python3.5/site-packages/django/contrib/sessions/backends/base.py", line 207, in _get_session
    self._session_cache = self.load()
  File "/home/django/.virtualenvs/edc-pharma/lib/python3.5/site-packages/django/contrib/sessions/backends/db.py", line 35, in load
    expire_date__gt=timezone.now()
  File "/home/django/.virtualenvs/edc-pharma/lib/python3.5/site-packages/django/db/models/manager.py", line 85, in manager_method
    return getattr(self.get_queryset(), name)(*args, **kwargs)
  File "/home/django/.virtualenvs/edc-pharma/lib/python3.5/site-packages/django/db/models/query.py", line 379, in get
    num = len(clone)
  File "/home/django/.virtualenvs/edc-pharma/lib/python3.5/site-packages/django/db/models/query.py", line 238, in __len__
    self._fetch_all()
  File "/home/django/.virtualenvs/edc-pharma/lib/python3.5/site-packages/django/db/models/query.py", line 1087, in _fetch_all
    self._result_cache = list(self.iterator())
  File "/home/django/.virtualenvs/edc-pharma/lib/python3.5/site-packages/django/db/models/query.py", line 54, in __iter__
    results = compiler.execute_sql()
  File "/home/django/.virtualenvs/edc-pharma/lib/python3.5/site-packages/django/db/models/sql/compiler.py", line 835, in execute_sql
    cursor.execute(sql, params)
  File "/home/django/.virtualenvs/edc-pharma/lib/python3.5/site-packages/django/db/backends/utils.py", line 79, in execute
    return super(CursorDebugWrapper, self).execute(sql, params)
  File "/home/django/.virtualenvs/edc-pharma/lib/python3.5/site-packages/django/db/backends/utils.py", line 64, in execute
    return self.cursor.execute(sql, params)
  File "/home/django/.virtualenvs/edc-pharma/lib/python3.5/site-packages/django/db/utils.py", line 94, in __exit__
    six.reraise(dj_exc_type, dj_exc_value, traceback)
  File "/home/django/.virtualenvs/edc-pharma/lib/python3.5/site-packages/django/utils/six.py", line 685, in reraise
    raise value.with_traceback(tb)
  File "/home/django/.virtualenvs/edc-pharma/lib/python3.5/site-packages/django/db/backends/utils.py", line 64, in execute
    return self.cursor.execute(sql, params)
  File "/home/django/.virtualenvs/edc-pharma/lib/python3.5/site-packages/django/db/backends/sqlite3/base.py", line 337, in execute
    return Database.Cursor.execute(self, query, params)
django.db.utils.OperationalError: no such table: django_session

During handling of the above exception, another exception occurred:

Traceback (most recent call last):
  File "/home/django/.virtualenvs/edc-pharma/lib/python3.5/site-packages/django/contrib/sessions/backends/base.py", line 202, in _get_session
    return self._session_cache
AttributeError: 'SessionStore' object has no attribute '_session_cache'

During handling of the above exception, another exception occurred:

Traceback (most recent call last):
  File "/home/django/.virtualenvs/edc-pharma/lib/python3.5/site-packages/django/db/backends/utils.py", line 64, in execute
    return self.cursor.execute(sql, params)
  File "/home/django/.virtualenvs/edc-pharma/lib/python3.5/site-packages/django/db/backends/sqlite3/base.py", line 337, in execute
    return Database.Cursor.execute(self, query, params)
sqlite3.OperationalError: no such table: django_session

The above exception was the direct cause of the following exception:

Traceback (most recent call last):
  File "/home/django/.virtualenvs/edc-pharma/lib/python3.5/site-packages/gunicorn/workers/sync.py", line 135, in handle
    self.handle_request(listener, req, client, addr)
  File "/home/django/.virtualenvs/edc-pharma/lib/python3.5/site-packages/gunicorn/workers/sync.py", line 176, in handle_request
    respiter = self.wsgi(environ, resp.start_response)
  File "/home/django/.virtualenvs/edc-pharma/lib/python3.5/site-packages/django/core/handlers/wsgi.py", line 170, in __call__
    response = self.get_response(request)
  File "/home/django/.virtualenvs/edc-pharma/lib/python3.5/site-packages/django/core/handlers/base.py", line 124, in get_response
    response = self._middleware_chain(request)
  File "/home/django/.virtualenvs/edc-pharma/lib/python3.5/site-packages/django/core/handlers/exception.py", line 41, in inner
    response = response_for_exception(request, exc)
  File "/home/django/.virtualenvs/edc-pharma/lib/python3.5/site-packages/django/core/handlers/exception.py", line 86, in response_for_exception
    response = handle_uncaught_exception(request, get_resolver(get_urlconf()), sys.exc_info())
  File "/home/django/.virtualenvs/edc-pharma/lib/python3.5/site-packages/django/core/handlers/exception.py", line 128, in handle_uncaught_exception
    return debug.technical_500_response(request, *exc_info)
  File "/home/django/.virtualenvs/edc-pharma/lib/python3.5/site-packages/django/views/debug.py", line 84, in technical_500_response
    html = reporter.get_traceback_html()
  File "/home/django/.virtualenvs/edc-pharma/lib/python3.5/site-packages/django/views/debug.py", line 317, in get_traceback_html
    return t.render(c)
  File "/home/django/.virtualenvs/edc-pharma/lib/python3.5/site-packages/django/template/base.py", line 208, in render
    return self._render(context)
  File "/home/django/.virtualenvs/edc-pharma/lib/python3.5/site-packages/django/template/base.py", line 199, in _render
    return self.nodelist.render(context)
  File "/home/django/.virtualenvs/edc-pharma/lib/python3.5/site-packages/django/template/base.py", line 994, in render
    bit = node.render_annotated(context)
  File "/home/django/.virtualenvs/edc-pharma/lib/python3.5/site-packages/django/template/base.py", line 961, in render_annotated
    return self.render(context)
  File "/home/django/.virtualenvs/edc-pharma/lib/python3.5/site-packages/django/template/defaulttags.py", line 315, in render
    return nodelist.render(context)
  File "/home/django/.virtualenvs/edc-pharma/lib/python3.5/site-packages/django/template/base.py", line 994, in render
    bit = node.render_annotated(context)
  File "/home/django/.virtualenvs/edc-pharma/lib/python3.5/site-packages/django/template/base.py", line 961, in render_annotated
    return self.render(context)
  File "/home/django/.virtualenvs/edc-pharma/lib/python3.5/site-packages/django/template/defaulttags.py", line 314, in render
    if match:
  File "/home/django/.virtualenvs/edc-pharma/lib/python3.5/site-packages/django/utils/functional.py", line 234, in inner
    self._setup()
  File "/home/django/.virtualenvs/edc-pharma/lib/python3.5/site-packages/django/utils/functional.py", line 380, in _setup
    self._wrapped = self._setupfunc()
  File "/home/django/.virtualenvs/edc-pharma/lib/python3.5/site-packages/django/contrib/auth/middleware.py", line 24, in <lambda>
    request.user = SimpleLazyObject(lambda: get_user(request))
  File "/home/django/.virtualenvs/edc-pharma/lib/python3.5/site-packages/django/contrib/auth/middleware.py", line 12, in get_user
    request._cached_user = auth.get_user(request)
  File "/home/django/.virtualenvs/edc-pharma/lib/python3.5/site-packages/django/contrib/auth/__init__.py", line 180, in get_user
    user_id = _get_user_session_key(request)
  File "/home/django/.virtualenvs/edc-pharma/lib/python3.5/site-packages/django/contrib/auth/__init__.py", line 59, in _get_user_session_key
    return get_user_model()._meta.pk.to_python(request.session[SESSION_KEY])
  File "/home/django/.virtualenvs/edc-pharma/lib/python3.5/site-packages/django/contrib/sessions/backends/base.py", line 57, in __getitem__
    return self._session[key]
  File "/home/django/.virtualenvs/edc-pharma/lib/python3.5/site-packages/django/contrib/sessions/backends/base.py", line 207, in _get_session
    self._session_cache = self.load()
  File "/home/django/.virtualenvs/edc-pharma/lib/python3.5/site-packages/django/contrib/sessions/backends/db.py", line 35, in load
    expire_date__gt=timezone.now()
  File "/home/django/.virtualenvs/edc-pharma/lib/python3.5/site-packages/django/db/models/manager.py", line 85, in manager_method
    return getattr(self.get_queryset(), name)(*args, **kwargs)
  File "/home/django/.virtualenvs/edc-pharma/lib/python3.5/site-packages/django/db/models/query.py", line 379, in get
    num = len(clone)
  File "/home/django/.virtualenvs/edc-pharma/lib/python3.5/site-packages/django/db/models/query.py", line 238, in __len__
    self._fetch_all()
  File "/home/django/.virtualenvs/edc-pharma/lib/python3.5/site-packages/django/db/models/query.py", line 1087, in _fetch_all
    self._result_cache = list(self.iterator())
  File "/home/django/.virtualenvs/edc-pharma/lib/python3.5/site-packages/django/db/models/query.py", line 54, in __iter__
    results = compiler.execute_sql()
  File "/home/django/.virtualenvs/edc-pharma/lib/python3.5/site-packages/django/db/models/sql/compiler.py", line 835, in execute_sql
    cursor.execute(sql, params)
  File "/home/django/.virtualenvs/edc-pharma/lib/python3.5/site-packages/django/db/backends/utils.py", line 79, in execute
    return super(CursorDebugWrapper, self).execute(sql, params)
  File "/home/django/.virtualenvs/edc-pharma/lib/python3.5/site-packages/django/db/backends/utils.py", line 64, in execute
    return self.cursor.execute(sql, params)
  File "/home/django/.virtualenvs/edc-pharma/lib/python3.5/site-packages/django/db/utils.py", line 94, in __exit__
    six.reraise(dj_exc_type, dj_exc_value, traceback)
  File "/home/django/.virtualenvs/edc-pharma/lib/python3.5/site-packages/django/utils/six.py", line 685, in reraise
    raise value.with_traceback(tb)
  File "/home/django/.virtualenvs/edc-pharma/lib/python3.5/site-packages/django/db/backends/utils.py", line 64, in execute
    return self.cursor.execute(sql, params)
  File "/home/django/.virtualenvs/edc-pharma/lib/python3.5/site-packages/django/db/backends/sqlite3/base.py", line 337, in execute
    return Database.Cursor.execute(self, query, params)
django.db.utils.OperationalError: no such table: django_session
[2016-11-03 13:10:03 +0200] [10816] [DEBUG] Current configuration:
  check_config: False
  loglevel: debug
  preload_app: False
  daemon: True
  raw_env: []
  pidfile: logs/gunicorn.pid
  secure_scheme_headers: {'X-FORWARDED-PROTO': 'https', 'X-FORWARDED-PROTOCOL': 'ssl', 'X-FORWARDED-SSL': 'on'}
  paste: None
  do_handshake_on_connect: False
  on_starting: <function OnStarting.on_starting at 0x7ff042457488>
  worker_tmp_dir: None
  statsd_prefix: 
  pythonpath: None
  proxy_protocol: False
  config: gunicorn.conf.py
  limit_request_fields: 100
  workers: 1
  max_requests_jitter: 0
  enable_stdio_inheritance: False
  proxy_allow_ips: ['127.0.0.1']
  keyfile: None
  ssl_version: 3
  errorlog: /home/django/source/edc-pharma/logs/gunicorn-error.log
  cert_reqs: 0
  forwarded_allow_ips: ['127.0.0.1']
  post_fork: <function Postfork.post_fork at 0x7ff042457ae8>
  capture_output: False
  worker_exit: <function WorkerExit.worker_exit at 0x7ff042461620>
  proc_name: None
  syslog_addr: udp://localhost:514
  spew: False
  max_requests: 0
  logger_class: gunicorn.glogging.Logger
  graceful_timeout: 30
  limit_request_line: 4094
  tmp_upload_dir: None
  nworkers_changed: <function NumWorkersChanged.nworkers_changed at 0x7ff0424617b8>
  ciphers: TLSv1
  django_settings: None
  worker_connections: 1000
  on_reload: <function OnReload.on_reload at 0x7ff042457620>
  when_ready: <function WhenReady.when_ready at 0x7ff0424577b8>
  pre_fork: <function Prefork.pre_fork at 0x7ff042457950>
  post_worker_init: <function PostWorkerInit.post_worker_init at 0x7ff042457c80>
  worker_int: <function WorkerInt.worker_int at 0x7ff042457e18>
  worker_abort: <function WorkerAbort.worker_abort at 0x7ff042461048>
  pre_exec: <function PreExec.pre_exec at 0x7ff0424611e0>
  on_exit: <function OnExit.on_exit at 0x7ff042461950>
  user: 1004
  group: 1004
  post_request: <function PostRequest.post_request at 0x7ff042461488>
  accesslog: /home/django/source/edc-pharma/logs/gunicorn-access.log
  access_log_format: %(h)s %(l)s %(u)s %(t)s "%(r)s" %(s)s %(b)s "%(f)s" "%(a)s"
  syslog: False
  chdir: /home/django/source/edc-pharma
  limit_request_field_size: 8190
  pre_request: <function PreRequest.pre_request at 0x7ff042461378>
  certfile: None
  ca_certs: None
  logconfig: None
  statsd_host: None
  umask: 0
  worker_class: sync
  timeout: 30
  keepalive: 2
  bind: ['127.0.0.1:9000']
  threads: 1
  sendfile: None
  syslog_prefix: None
  default_proc_name: edc_pharma.wsgi
  backlog: 2048
  syslog_facility: user
  suppress_ragged_eofs: True
  reload: False
[2016-11-03 13:10:03 +0200] [10816] [INFO] Starting gunicorn 19.6.0
[2016-11-03 13:10:06 +0200] [10757] [DEBUG] GET /
[2016-11-03 13:10:15 +0200] [10757] [ERROR] Error handling request /
Traceback (most recent call last):
  File "/home/django/.virtualenvs/edc-pharma/lib/python3.5/site-packages/django/contrib/sessions/backends/base.py", line 202, in _get_session
    return self._session_cache
AttributeError: 'SessionStore' object has no attribute '_session_cache'

During handling of the above exception, another exception occurred:

Traceback (most recent call last):
  File "/home/django/.virtualenvs/edc-pharma/lib/python3.5/site-packages/django/db/backends/utils.py", line 64, in execute
    return self.cursor.execute(sql, params)
  File "/home/django/.virtualenvs/edc-pharma/lib/python3.5/site-packages/django/db/backends/sqlite3/base.py", line 337, in execute
    return Database.Cursor.execute(self, query, params)
sqlite3.OperationalError: no such table: django_session

The above exception was the direct cause of the following exception:

Traceback (most recent call last):
  File "/home/django/.virtualenvs/edc-pharma/lib/python3.5/site-packages/django/core/handlers/exception.py", line 39, in inner
    response = get_response(request)
  File "/home/django/.virtualenvs/edc-pharma/lib/python3.5/site-packages/django/core/handlers/base.py", line 187, in _get_response
    response = self.process_exception_by_middleware(e, request)
  File "/home/django/.virtualenvs/edc-pharma/lib/python3.5/site-packages/django/core/handlers/base.py", line 185, in _get_response
    response = wrapped_callback(request, *callback_args, **callback_kwargs)
  File "/home/django/.virtualenvs/edc-pharma/lib/python3.5/site-packages/django/views/generic/base.py", line 68, in view
    return self.dispatch(request, *args, **kwargs)
  File "/home/django/.virtualenvs/edc-pharma/lib/python3.5/site-packages/django/utils/decorators.py", line 67, in _wrapper
    return bound_func(*args, **kwargs)
  File "/home/django/.virtualenvs/edc-pharma/lib/python3.5/site-packages/django/contrib/auth/decorators.py", line 22, in _wrapped_view
    if test_func(request.user):
  File "/home/django/.virtualenvs/edc-pharma/lib/python3.5/site-packages/django/contrib/auth/decorators.py", line 46, in <lambda>
    lambda u: u.is_authenticated,
  File "/home/django/.virtualenvs/edc-pharma/lib/python3.5/site-packages/django/utils/functional.py", line 234, in inner
    self._setup()
  File "/home/django/.virtualenvs/edc-pharma/lib/python3.5/site-packages/django/utils/functional.py", line 380, in _setup
    self._wrapped = self._setupfunc()
  File "/home/django/.virtualenvs/edc-pharma/lib/python3.5/site-packages/django/contrib/auth/middleware.py", line 24, in <lambda>
    request.user = SimpleLazyObject(lambda: get_user(request))
  File "/home/django/.virtualenvs/edc-pharma/lib/python3.5/site-packages/django/contrib/auth/middleware.py", line 12, in get_user
    request._cached_user = auth.get_user(request)
  File "/home/django/.virtualenvs/edc-pharma/lib/python3.5/site-packages/django/contrib/auth/__init__.py", line 180, in get_user
    user_id = _get_user_session_key(request)
  File "/home/django/.virtualenvs/edc-pharma/lib/python3.5/site-packages/django/contrib/auth/__init__.py", line 59, in _get_user_session_key
    return get_user_model()._meta.pk.to_python(request.session[SESSION_KEY])
  File "/home/django/.virtualenvs/edc-pharma/lib/python3.5/site-packages/django/contrib/sessions/backends/base.py", line 57, in __getitem__
    return self._session[key]
  File "/home/django/.virtualenvs/edc-pharma/lib/python3.5/site-packages/django/contrib/sessions/backends/base.py", line 207, in _get_session
    self._session_cache = self.load()
  File "/home/django/.virtualenvs/edc-pharma/lib/python3.5/site-packages/django/contrib/sessions/backends/db.py", line 35, in load
    expire_date__gt=timezone.now()
  File "/home/django/.virtualenvs/edc-pharma/lib/python3.5/site-packages/django/db/models/manager.py", line 85, in manager_method
    return getattr(self.get_queryset(), name)(*args, **kwargs)
  File "/home/django/.virtualenvs/edc-pharma/lib/python3.5/site-packages/django/db/models/query.py", line 379, in get
    num = len(clone)
  File "/home/django/.virtualenvs/edc-pharma/lib/python3.5/site-packages/django/db/models/query.py", line 238, in __len__
    self._fetch_all()
  File "/home/django/.virtualenvs/edc-pharma/lib/python3.5/site-packages/django/db/models/query.py", line 1087, in _fetch_all
    self._result_cache = list(self.iterator())
  File "/home/django/.virtualenvs/edc-pharma/lib/python3.5/site-packages/django/db/models/query.py", line 54, in __iter__
    results = compiler.execute_sql()
  File "/home/django/.virtualenvs/edc-pharma/lib/python3.5/site-packages/django/db/models/sql/compiler.py", line 835, in execute_sql
    cursor.execute(sql, params)
  File "/home/django/.virtualenvs/edc-pharma/lib/python3.5/site-packages/django/db/backends/utils.py", line 79, in execute
    return super(CursorDebugWrapper, self).execute(sql, params)
  File "/home/django/.virtualenvs/edc-pharma/lib/python3.5/site-packages/django/db/backends/utils.py", line 64, in execute
    return self.cursor.execute(sql, params)
  File "/home/django/.virtualenvs/edc-pharma/lib/python3.5/site-packages/django/db/utils.py", line 94, in __exit__
    six.reraise(dj_exc_type, dj_exc_value, traceback)
  File "/home/django/.virtualenvs/edc-pharma/lib/python3.5/site-packages/django/utils/six.py", line 685, in reraise
    raise value.with_traceback(tb)
  File "/home/django/.virtualenvs/edc-pharma/lib/python3.5/site-packages/django/db/backends/utils.py", line 64, in execute
    return self.cursor.execute(sql, params)
  File "/home/django/.virtualenvs/edc-pharma/lib/python3.5/site-packages/django/db/backends/sqlite3/base.py", line 337, in execute
    return Database.Cursor.execute(self, query, params)
django.db.utils.OperationalError: no such table: django_session

During handling of the above exception, another exception occurred:

Traceback (most recent call last):
  File "/home/django/.virtualenvs/edc-pharma/lib/python3.5/site-packages/django/contrib/sessions/backends/base.py", line 202, in _get_session
    return self._session_cache
AttributeError: 'SessionStore' object has no attribute '_session_cache'

During handling of the above exception, another exception occurred:

Traceback (most recent call last):
  File "/home/django/.virtualenvs/edc-pharma/lib/python3.5/site-packages/django/db/backends/utils.py", line 64, in execute
    return self.cursor.execute(sql, params)
  File "/home/django/.virtualenvs/edc-pharma/lib/python3.5/site-packages/django/db/backends/sqlite3/base.py", line 337, in execute
    return Database.Cursor.execute(self, query, params)
sqlite3.OperationalError: no such table: django_session

The above exception was the direct cause of the following exception:

Traceback (most recent call last):
  File "/home/django/.virtualenvs/edc-pharma/lib/python3.5/site-packages/django/core/handlers/exception.py", line 39, in inner
    response = get_response(request)
  File "/home/django/.virtualenvs/edc-pharma/lib/python3.5/site-packages/django/utils/deprecation.py", line 133, in __call__
    response = self.get_response(request)
  File "/home/django/.virtualenvs/edc-pharma/lib/python3.5/site-packages/django/core/handlers/exception.py", line 41, in inner
    response = response_for_exception(request, exc)
  File "/home/django/.virtualenvs/edc-pharma/lib/python3.5/site-packages/django/core/handlers/exception.py", line 86, in response_for_exception
    response = handle_uncaught_exception(request, get_resolver(get_urlconf()), sys.exc_info())
  File "/home/django/.virtualenvs/edc-pharma/lib/python3.5/site-packages/django/core/handlers/exception.py", line 128, in handle_uncaught_exception
    return debug.technical_500_response(request, *exc_info)
  File "/home/django/.virtualenvs/edc-pharma/lib/python3.5/site-packages/django/views/debug.py", line 84, in technical_500_response
    html = reporter.get_traceback_html()
  File "/home/django/.virtualenvs/edc-pharma/lib/python3.5/site-packages/django/views/debug.py", line 317, in get_traceback_html
    return t.render(c)
  File "/home/django/.virtualenvs/edc-pharma/lib/python3.5/site-packages/django/template/base.py", line 208, in render
    return self._render(context)
  File "/home/django/.virtualenvs/edc-pharma/lib/python3.5/site-packages/django/template/base.py", line 199, in _render
    return self.nodelist.render(context)
  File "/home/django/.virtualenvs/edc-pharma/lib/python3.5/site-packages/django/template/base.py", line 994, in render
    bit = node.render_annotated(context)
  File "/home/django/.virtualenvs/edc-pharma/lib/python3.5/site-packages/django/template/base.py", line 961, in render_annotated
    return self.render(context)
  File "/home/django/.virtualenvs/edc-pharma/lib/python3.5/site-packages/django/template/defaulttags.py", line 315, in render
    return nodelist.render(context)
  File "/home/django/.virtualenvs/edc-pharma/lib/python3.5/site-packages/django/template/base.py", line 994, in render
    bit = node.render_annotated(context)
  File "/home/django/.virtualenvs/edc-pharma/lib/python3.5/site-packages/django/template/base.py", line 961, in render_annotated
    return self.render(context)
  File "/home/django/.virtualenvs/edc-pharma/lib/python3.5/site-packages/django/template/defaulttags.py", line 314, in render
    if match:
  File "/home/django/.virtualenvs/edc-pharma/lib/python3.5/site-packages/django/utils/functional.py", line 234, in inner
    self._setup()
  File "/home/django/.virtualenvs/edc-pharma/lib/python3.5/site-packages/django/utils/functional.py", line 380, in _setup
    self._wrapped = self._setupfunc()
  File "/home/django/.virtualenvs/edc-pharma/lib/python3.5/site-packages/django/contrib/auth/middleware.py", line 24, in <lambda>
    request.user = SimpleLazyObject(lambda: get_user(request))
  File "/home/django/.virtualenvs/edc-pharma/lib/python3.5/site-packages/django/contrib/auth/middleware.py", line 12, in get_user
    request._cached_user = auth.get_user(request)
  File "/home/django/.virtualenvs/edc-pharma/lib/python3.5/site-packages/django/contrib/auth/__init__.py", line 180, in get_user
    user_id = _get_user_session_key(request)
  File "/home/django/.virtualenvs/edc-pharma/lib/python3.5/site-packages/django/contrib/auth/__init__.py", line 59, in _get_user_session_key
    return get_user_model()._meta.pk.to_python(request.session[SESSION_KEY])
  File "/home/django/.virtualenvs/edc-pharma/lib/python3.5/site-packages/django/contrib/sessions/backends/base.py", line 57, in __getitem__
    return self._session[key]
  File "/home/django/.virtualenvs/edc-pharma/lib/python3.5/site-packages/django/contrib/sessions/backends/base.py", line 207, in _get_session
    self._session_cache = self.load()
  File "/home/django/.virtualenvs/edc-pharma/lib/python3.5/site-packages/django/contrib/sessions/backends/db.py", line 35, in load
    expire_date__gt=timezone.now()
  File "/home/django/.virtualenvs/edc-pharma/lib/python3.5/site-packages/django/db/models/manager.py", line 85, in manager_method
    return getattr(self.get_queryset(), name)(*args, **kwargs)
  File "/home/django/.virtualenvs/edc-pharma/lib/python3.5/site-packages/django/db/models/query.py", line 379, in get
    num = len(clone)
  File "/home/django/.virtualenvs/edc-pharma/lib/python3.5/site-packages/django/db/models/query.py", line 238, in __len__
    self._fetch_all()
  File "/home/django/.virtualenvs/edc-pharma/lib/python3.5/site-packages/django/db/models/query.py", line 1087, in _fetch_all
    self._result_cache = list(self.iterator())
  File "/home/django/.virtualenvs/edc-pharma/lib/python3.5/site-packages/django/db/models/query.py", line 54, in __iter__
    results = compiler.execute_sql()
  File "/home/django/.virtualenvs/edc-pharma/lib/python3.5/site-packages/django/db/models/sql/compiler.py", line 835, in execute_sql
    cursor.execute(sql, params)
  File "/home/django/.virtualenvs/edc-pharma/lib/python3.5/site-packages/django/db/backends/utils.py", line 79, in execute
    return super(CursorDebugWrapper, self).execute(sql, params)
  File "/home/django/.virtualenvs/edc-pharma/lib/python3.5/site-packages/django/db/backends/utils.py", line 64, in execute
    return self.cursor.execute(sql, params)
  File "/home/django/.virtualenvs/edc-pharma/lib/python3.5/site-packages/django/db/utils.py", line 94, in __exit__
    six.reraise(dj_exc_type, dj_exc_value, traceback)
  File "/home/django/.virtualenvs/edc-pharma/lib/python3.5/site-packages/django/utils/six.py", line 685, in reraise
    raise value.with_traceback(tb)
  File "/home/django/.virtualenvs/edc-pharma/lib/python3.5/site-packages/django/db/backends/utils.py", line 64, in execute
    return self.cursor.execute(sql, params)
  File "/home/django/.virtualenvs/edc-pharma/lib/python3.5/site-packages/django/db/backends/sqlite3/base.py", line 337, in execute
    return Database.Cursor.execute(self, query, params)
django.db.utils.OperationalError: no such table: django_session

During handling of the above exception, another exception occurred:

Traceback (most recent call last):
  File "/home/django/.virtualenvs/edc-pharma/lib/python3.5/site-packages/django/contrib/sessions/backends/base.py", line 202, in _get_session
    return self._session_cache
AttributeError: 'SessionStore' object has no attribute '_session_cache'

During handling of the above exception, another exception occurred:

Traceback (most recent call last):
  File "/home/django/.virtualenvs/edc-pharma/lib/python3.5/site-packages/django/db/backends/utils.py", line 64, in execute
    return self.cursor.execute(sql, params)
  File "/home/django/.virtualenvs/edc-pharma/lib/python3.5/site-packages/django/db/backends/sqlite3/base.py", line 337, in execute
    return Database.Cursor.execute(self, query, params)
sqlite3.OperationalError: no such table: django_session

The above exception was the direct cause of the following exception:

Traceback (most recent call last):
  File "/home/django/.virtualenvs/edc-pharma/lib/python3.5/site-packages/django/core/handlers/exception.py", line 39, in inner
    response = get_response(request)
  File "/home/django/.virtualenvs/edc-pharma/lib/python3.5/site-packages/django/utils/deprecation.py", line 133, in __call__
    response = self.get_response(request)
  File "/home/django/.virtualenvs/edc-pharma/lib/python3.5/site-packages/django/core/handlers/exception.py", line 41, in inner
    response = response_for_exception(request, exc)
  File "/home/django/.virtualenvs/edc-pharma/lib/python3.5/site-packages/django/core/handlers/exception.py", line 86, in response_for_exception
    response = handle_uncaught_exception(request, get_resolver(get_urlconf()), sys.exc_info())
  File "/home/django/.virtualenvs/edc-pharma/lib/python3.5/site-packages/django/core/handlers/exception.py", line 128, in handle_uncaught_exception
    return debug.technical_500_response(request, *exc_info)
  File "/home/django/.virtualenvs/edc-pharma/lib/python3.5/site-packages/django/views/debug.py", line 84, in technical_500_response
    html = reporter.get_traceback_html()
  File "/home/django/.virtualenvs/edc-pharma/lib/python3.5/site-packages/django/views/debug.py", line 317, in get_traceback_html
    return t.render(c)
  File "/home/django/.virtualenvs/edc-pharma/lib/python3.5/site-packages/django/template/base.py", line 208, in render
    return self._render(context)
  File "/home/django/.virtualenvs/edc-pharma/lib/python3.5/site-packages/django/template/base.py", line 199, in _render
    return self.nodelist.render(context)
  File "/home/django/.virtualenvs/edc-pharma/lib/python3.5/site-packages/django/template/base.py", line 994, in render
    bit = node.render_annotated(context)
  File "/home/django/.virtualenvs/edc-pharma/lib/python3.5/site-packages/django/template/base.py", line 961, in render_annotated
    return self.render(context)
  File "/home/django/.virtualenvs/edc-pharma/lib/python3.5/site-packages/django/template/defaulttags.py", line 315, in render
    return nodelist.render(context)
  File "/home/django/.virtualenvs/edc-pharma/lib/python3.5/site-packages/django/template/base.py", line 994, in render
    bit = node.render_annotated(context)
  File "/home/django/.virtualenvs/edc-pharma/lib/python3.5/site-packages/django/template/base.py", line 961, in render_annotated
    return self.render(context)
  File "/home/django/.virtualenvs/edc-pharma/lib/python3.5/site-packages/django/template/defaulttags.py", line 314, in render
    if match:
  File "/home/django/.virtualenvs/edc-pharma/lib/python3.5/site-packages/django/utils/functional.py", line 234, in inner
    self._setup()
  File "/home/django/.virtualenvs/edc-pharma/lib/python3.5/site-packages/django/utils/functional.py", line 380, in _setup
    self._wrapped = self._setupfunc()
  File "/home/django/.virtualenvs/edc-pharma/lib/python3.5/site-packages/django/contrib/auth/middleware.py", line 24, in <lambda>
    request.user = SimpleLazyObject(lambda: get_user(request))
  File "/home/django/.virtualenvs/edc-pharma/lib/python3.5/site-packages/django/contrib/auth/middleware.py", line 12, in get_user
    request._cached_user = auth.get_user(request)
  File "/home/django/.virtualenvs/edc-pharma/lib/python3.5/site-packages/django/contrib/auth/__init__.py", line 180, in get_user
    user_id = _get_user_session_key(request)
  File "/home/django/.virtualenvs/edc-pharma/lib/python3.5/site-packages/django/contrib/auth/__init__.py", line 59, in _get_user_session_key
    return get_user_model()._meta.pk.to_python(request.session[SESSION_KEY])
  File "/home/django/.virtualenvs/edc-pharma/lib/python3.5/site-packages/django/contrib/sessions/backends/base.py", line 57, in __getitem__
    return self._session[key]
  File "/home/django/.virtualenvs/edc-pharma/lib/python3.5/site-packages/django/contrib/sessions/backends/base.py", line 207, in _get_session
    self._session_cache = self.load()
  File "/home/django/.virtualenvs/edc-pharma/lib/python3.5/site-packages/django/contrib/sessions/backends/db.py", line 35, in load
    expire_date__gt=timezone.now()
  File "/home/django/.virtualenvs/edc-pharma/lib/python3.5/site-packages/django/db/models/manager.py", line 85, in manager_method
    return getattr(self.get_queryset(), name)(*args, **kwargs)
  File "/home/django/.virtualenvs/edc-pharma/lib/python3.5/site-packages/django/db/models/query.py", line 379, in get
    num = len(clone)
  File "/home/django/.virtualenvs/edc-pharma/lib/python3.5/site-packages/django/db/models/query.py", line 238, in __len__
    self._fetch_all()
  File "/home/django/.virtualenvs/edc-pharma/lib/python3.5/site-packages/django/db/models/query.py", line 1087, in _fetch_all
    self._result_cache = list(self.iterator())
  File "/home/django/.virtualenvs/edc-pharma/lib/python3.5/site-packages/django/db/models/query.py", line 54, in __iter__
    results = compiler.execute_sql()
  File "/home/django/.virtualenvs/edc-pharma/lib/python3.5/site-packages/django/db/models/sql/compiler.py", line 835, in execute_sql
    cursor.execute(sql, params)
  File "/home/django/.virtualenvs/edc-pharma/lib/python3.5/site-packages/django/db/backends/utils.py", line 79, in execute
    return super(CursorDebugWrapper, self).execute(sql, params)
  File "/home/django/.virtualenvs/edc-pharma/lib/python3.5/site-packages/django/db/backends/utils.py", line 64, in execute
    return self.cursor.execute(sql, params)
  File "/home/django/.virtualenvs/edc-pharma/lib/python3.5/site-packages/django/db/utils.py", line 94, in __exit__
    six.reraise(dj_exc_type, dj_exc_value, traceback)
  File "/home/django/.virtualenvs/edc-pharma/lib/python3.5/site-packages/django/utils/six.py", line 685, in reraise
    raise value.with_traceback(tb)
  File "/home/django/.virtualenvs/edc-pharma/lib/python3.5/site-packages/django/db/backends/utils.py", line 64, in execute
    return self.cursor.execute(sql, params)
  File "/home/django/.virtualenvs/edc-pharma/lib/python3.5/site-packages/django/db/backends/sqlite3/base.py", line 337, in execute
    return Database.Cursor.execute(self, query, params)
django.db.utils.OperationalError: no such table: django_session

During handling of the above exception, another exception occurred:

Traceback (most recent call last):
  File "/home/django/.virtualenvs/edc-pharma/lib/python3.5/site-packages/django/contrib/sessions/backends/base.py", line 202, in _get_session
    return self._session_cache
AttributeError: 'SessionStore' object has no attribute '_session_cache'

During handling of the above exception, another exception occurred:

Traceback (most recent call last):
  File "/home/django/.virtualenvs/edc-pharma/lib/python3.5/site-packages/django/db/backends/utils.py", line 64, in execute
    return self.cursor.execute(sql, params)
  File "/home/django/.virtualenvs/edc-pharma/lib/python3.5/site-packages/django/db/backends/sqlite3/base.py", line 337, in execute
    return Database.Cursor.execute(self, query, params)
sqlite3.OperationalError: no such table: django_session

The above exception was the direct cause of the following exception:

Traceback (most recent call last):
  File "/home/django/.virtualenvs/edc-pharma/lib/python3.5/site-packages/django/core/handlers/exception.py", line 39, in inner
    response = get_response(request)
  File "/home/django/.virtualenvs/edc-pharma/lib/python3.5/site-packages/django/utils/deprecation.py", line 133, in __call__
    response = self.get_response(request)
  File "/home/django/.virtualenvs/edc-pharma/lib/python3.5/site-packages/django/core/handlers/exception.py", line 41, in inner
    response = response_for_exception(request, exc)
  File "/home/django/.virtualenvs/edc-pharma/lib/python3.5/site-packages/django/core/handlers/exception.py", line 86, in response_for_exception
    response = handle_uncaught_exception(request, get_resolver(get_urlconf()), sys.exc_info())
  File "/home/django/.virtualenvs/edc-pharma/lib/python3.5/site-packages/django/core/handlers/exception.py", line 128, in handle_uncaught_exception
    return debug.technical_500_response(request, *exc_info)
  File "/home/django/.virtualenvs/edc-pharma/lib/python3.5/site-packages/django/views/debug.py", line 84, in technical_500_response
    html = reporter.get_traceback_html()
  File "/home/django/.virtualenvs/edc-pharma/lib/python3.5/site-packages/django/views/debug.py", line 317, in get_traceback_html
    return t.render(c)
  File "/home/django/.virtualenvs/edc-pharma/lib/python3.5/site-packages/django/template/base.py", line 208, in render
    return self._render(context)
  File "/home/django/.virtualenvs/edc-pharma/lib/python3.5/site-packages/django/template/base.py", line 199, in _render
    return self.nodelist.render(context)
  File "/home/django/.virtualenvs/edc-pharma/lib/python3.5/site-packages/django/template/base.py", line 994, in render
    bit = node.render_annotated(context)
  File "/home/django/.virtualenvs/edc-pharma/lib/python3.5/site-packages/django/template/base.py", line 961, in render_annotated
    return self.render(context)
  File "/home/django/.virtualenvs/edc-pharma/lib/python3.5/site-packages/django/template/defaulttags.py", line 315, in render
    return nodelist.render(context)
  File "/home/django/.virtualenvs/edc-pharma/lib/python3.5/site-packages/django/template/base.py", line 994, in render
    bit = node.render_annotated(context)
  File "/home/django/.virtualenvs/edc-pharma/lib/python3.5/site-packages/django/template/base.py", line 961, in render_annotated
    return self.render(context)
  File "/home/django/.virtualenvs/edc-pharma/lib/python3.5/site-packages/django/template/defaulttags.py", line 314, in render
    if match:
  File "/home/django/.virtualenvs/edc-pharma/lib/python3.5/site-packages/django/utils/functional.py", line 234, in inner
    self._setup()
  File "/home/django/.virtualenvs/edc-pharma/lib/python3.5/site-packages/django/utils/functional.py", line 380, in _setup
    self._wrapped = self._setupfunc()
  File "/home/django/.virtualenvs/edc-pharma/lib/python3.5/site-packages/django/contrib/auth/middleware.py", line 24, in <lambda>
    request.user = SimpleLazyObject(lambda: get_user(request))
  File "/home/django/.virtualenvs/edc-pharma/lib/python3.5/site-packages/django/contrib/auth/middleware.py", line 12, in get_user
    request._cached_user = auth.get_user(request)
  File "/home/django/.virtualenvs/edc-pharma/lib/python3.5/site-packages/django/contrib/auth/__init__.py", line 180, in get_user
    user_id = _get_user_session_key(request)
  File "/home/django/.virtualenvs/edc-pharma/lib/python3.5/site-packages/django/contrib/auth/__init__.py", line 59, in _get_user_session_key
    return get_user_model()._meta.pk.to_python(request.session[SESSION_KEY])
  File "/home/django/.virtualenvs/edc-pharma/lib/python3.5/site-packages/django/contrib/sessions/backends/base.py", line 57, in __getitem__
    return self._session[key]
  File "/home/django/.virtualenvs/edc-pharma/lib/python3.5/site-packages/django/contrib/sessions/backends/base.py", line 207, in _get_session
    self._session_cache = self.load()
  File "/home/django/.virtualenvs/edc-pharma/lib/python3.5/site-packages/django/contrib/sessions/backends/db.py", line 35, in load
    expire_date__gt=timezone.now()
  File "/home/django/.virtualenvs/edc-pharma/lib/python3.5/site-packages/django/db/models/manager.py", line 85, in manager_method
    return getattr(self.get_queryset(), name)(*args, **kwargs)
  File "/home/django/.virtualenvs/edc-pharma/lib/python3.5/site-packages/django/db/models/query.py", line 379, in get
    num = len(clone)
  File "/home/django/.virtualenvs/edc-pharma/lib/python3.5/site-packages/django/db/models/query.py", line 238, in __len__
    self._fetch_all()
  File "/home/django/.virtualenvs/edc-pharma/lib/python3.5/site-packages/django/db/models/query.py", line 1087, in _fetch_all
    self._result_cache = list(self.iterator())
  File "/home/django/.virtualenvs/edc-pharma/lib/python3.5/site-packages/django/db/models/query.py", line 54, in __iter__
    results = compiler.execute_sql()
  File "/home/django/.virtualenvs/edc-pharma/lib/python3.5/site-packages/django/db/models/sql/compiler.py", line 835, in execute_sql
    cursor.execute(sql, params)
  File "/home/django/.virtualenvs/edc-pharma/lib/python3.5/site-packages/django/db/backends/utils.py", line 79, in execute
    return super(CursorDebugWrapper, self).execute(sql, params)
  File "/home/django/.virtualenvs/edc-pharma/lib/python3.5/site-packages/django/db/backends/utils.py", line 64, in execute
    return self.cursor.execute(sql, params)
  File "/home/django/.virtualenvs/edc-pharma/lib/python3.5/site-packages/django/db/utils.py", line 94, in __exit__
    six.reraise(dj_exc_type, dj_exc_value, traceback)
  File "/home/django/.virtualenvs/edc-pharma/lib/python3.5/site-packages/django/utils/six.py", line 685, in reraise
    raise value.with_traceback(tb)
  File "/home/django/.virtualenvs/edc-pharma/lib/python3.5/site-packages/django/db/backends/utils.py", line 64, in execute
    return self.cursor.execute(sql, params)
  File "/home/django/.virtualenvs/edc-pharma/lib/python3.5/site-packages/django/db/backends/sqlite3/base.py", line 337, in execute
    return Database.Cursor.execute(self, query, params)
django.db.utils.OperationalError: no such table: django_session

During handling of the above exception, another exception occurred:

Traceback (most recent call last):
  File "/home/django/.virtualenvs/edc-pharma/lib/python3.5/site-packages/django/contrib/sessions/backends/base.py", line 202, in _get_session
    return self._session_cache
AttributeError: 'SessionStore' object has no attribute '_session_cache'

During handling of the above exception, another exception occurred:

Traceback (most recent call last):
  File "/home/django/.virtualenvs/edc-pharma/lib/python3.5/site-packages/django/db/backends/utils.py", line 64, in execute
    return self.cursor.execute(sql, params)
  File "/home/django/.virtualenvs/edc-pharma/lib/python3.5/site-packages/django/db/backends/sqlite3/base.py", line 337, in execute
    return Database.Cursor.execute(self, query, params)
sqlite3.OperationalError: no such table: django_session

The above exception was the direct cause of the following exception:

Traceback (most recent call last):
  File "/home/django/.virtualenvs/edc-pharma/lib/python3.5/site-packages/django/core/handlers/exception.py", line 39, in inner
    response = get_response(request)
  File "/home/django/.virtualenvs/edc-pharma/lib/python3.5/site-packages/django/utils/deprecation.py", line 133, in __call__
    response = self.get_response(request)
  File "/home/django/.virtualenvs/edc-pharma/lib/python3.5/site-packages/django/core/handlers/exception.py", line 41, in inner
    response = response_for_exception(request, exc)
  File "/home/django/.virtualenvs/edc-pharma/lib/python3.5/site-packages/django/core/handlers/exception.py", line 86, in response_for_exception
    response = handle_uncaught_exception(request, get_resolver(get_urlconf()), sys.exc_info())
  File "/home/django/.virtualenvs/edc-pharma/lib/python3.5/site-packages/django/core/handlers/exception.py", line 128, in handle_uncaught_exception
    return debug.technical_500_response(request, *exc_info)
  File "/home/django/.virtualenvs/edc-pharma/lib/python3.5/site-packages/django/views/debug.py", line 84, in technical_500_response
    html = reporter.get_traceback_html()
  File "/home/django/.virtualenvs/edc-pharma/lib/python3.5/site-packages/django/views/debug.py", line 317, in get_traceback_html
    return t.render(c)
  File "/home/django/.virtualenvs/edc-pharma/lib/python3.5/site-packages/django/template/base.py", line 208, in render
    return self._render(context)
  File "/home/django/.virtualenvs/edc-pharma/lib/python3.5/site-packages/django/template/base.py", line 199, in _render
    return self.nodelist.render(context)
  File "/home/django/.virtualenvs/edc-pharma/lib/python3.5/site-packages/django/template/base.py", line 994, in render
    bit = node.render_annotated(context)
  File "/home/django/.virtualenvs/edc-pharma/lib/python3.5/site-packages/django/template/base.py", line 961, in render_annotated
    return self.render(context)
  File "/home/django/.virtualenvs/edc-pharma/lib/python3.5/site-packages/django/template/defaulttags.py", line 315, in render
    return nodelist.render(context)
  File "/home/django/.virtualenvs/edc-pharma/lib/python3.5/site-packages/django/template/base.py", line 994, in render
    bit = node.render_annotated(context)
  File "/home/django/.virtualenvs/edc-pharma/lib/python3.5/site-packages/django/template/base.py", line 961, in render_annotated
    return self.render(context)
  File "/home/django/.virtualenvs/edc-pharma/lib/python3.5/site-packages/django/template/defaulttags.py", line 314, in render
    if match:
  File "/home/django/.virtualenvs/edc-pharma/lib/python3.5/site-packages/django/utils/functional.py", line 234, in inner
    self._setup()
  File "/home/django/.virtualenvs/edc-pharma/lib/python3.5/site-packages/django/utils/functional.py", line 380, in _setup
    self._wrapped = self._setupfunc()
  File "/home/django/.virtualenvs/edc-pharma/lib/python3.5/site-packages/django/contrib/auth/middleware.py", line 24, in <lambda>
    request.user = SimpleLazyObject(lambda: get_user(request))
  File "/home/django/.virtualenvs/edc-pharma/lib/python3.5/site-packages/django/contrib/auth/middleware.py", line 12, in get_user
    request._cached_user = auth.get_user(request)
  File "/home/django/.virtualenvs/edc-pharma/lib/python3.5/site-packages/django/contrib/auth/__init__.py", line 180, in get_user
    user_id = _get_user_session_key(request)
  File "/home/django/.virtualenvs/edc-pharma/lib/python3.5/site-packages/django/contrib/auth/__init__.py", line 59, in _get_user_session_key
    return get_user_model()._meta.pk.to_python(request.session[SESSION_KEY])
  File "/home/django/.virtualenvs/edc-pharma/lib/python3.5/site-packages/django/contrib/sessions/backends/base.py", line 57, in __getitem__
    return self._session[key]
  File "/home/django/.virtualenvs/edc-pharma/lib/python3.5/site-packages/django/contrib/sessions/backends/base.py", line 207, in _get_session
    self._session_cache = self.load()
  File "/home/django/.virtualenvs/edc-pharma/lib/python3.5/site-packages/django/contrib/sessions/backends/db.py", line 35, in load
    expire_date__gt=timezone.now()
  File "/home/django/.virtualenvs/edc-pharma/lib/python3.5/site-packages/django/db/models/manager.py", line 85, in manager_method
    return getattr(self.get_queryset(), name)(*args, **kwargs)
  File "/home/django/.virtualenvs/edc-pharma/lib/python3.5/site-packages/django/db/models/query.py", line 379, in get
    num = len(clone)
  File "/home/django/.virtualenvs/edc-pharma/lib/python3.5/site-packages/django/db/models/query.py", line 238, in __len__
    self._fetch_all()
  File "/home/django/.virtualenvs/edc-pharma/lib/python3.5/site-packages/django/db/models/query.py", line 1087, in _fetch_all
    self._result_cache = list(self.iterator())
  File "/home/django/.virtualenvs/edc-pharma/lib/python3.5/site-packages/django/db/models/query.py", line 54, in __iter__
    results = compiler.execute_sql()
  File "/home/django/.virtualenvs/edc-pharma/lib/python3.5/site-packages/django/db/models/sql/compiler.py", line 835, in execute_sql
    cursor.execute(sql, params)
  File "/home/django/.virtualenvs/edc-pharma/lib/python3.5/site-packages/django/db/backends/utils.py", line 79, in execute
    return super(CursorDebugWrapper, self).execute(sql, params)
  File "/home/django/.virtualenvs/edc-pharma/lib/python3.5/site-packages/django/db/backends/utils.py", line 64, in execute
    return self.cursor.execute(sql, params)
  File "/home/django/.virtualenvs/edc-pharma/lib/python3.5/site-packages/django/db/utils.py", line 94, in __exit__
    six.reraise(dj_exc_type, dj_exc_value, traceback)
  File "/home/django/.virtualenvs/edc-pharma/lib/python3.5/site-packages/django/utils/six.py", line 685, in reraise
    raise value.with_traceback(tb)
  File "/home/django/.virtualenvs/edc-pharma/lib/python3.5/site-packages/django/db/backends/utils.py", line 64, in execute
    return self.cursor.execute(sql, params)
  File "/home/django/.virtualenvs/edc-pharma/lib/python3.5/site-packages/django/db/backends/sqlite3/base.py", line 337, in execute
    return Database.Cursor.execute(self, query, params)
django.db.utils.OperationalError: no such table: django_session

During handling of the above exception, another exception occurred:

Traceback (most recent call last):
  File "/home/django/.virtualenvs/edc-pharma/lib/python3.5/site-packages/django/contrib/sessions/backends/base.py", line 202, in _get_session
    return self._session_cache
AttributeError: 'SessionStore' object has no attribute '_session_cache'

During handling of the above exception, another exception occurred:

Traceback (most recent call last):
  File "/home/django/.virtualenvs/edc-pharma/lib/python3.5/site-packages/django/db/backends/utils.py", line 64, in execute
    return self.cursor.execute(sql, params)
  File "/home/django/.virtualenvs/edc-pharma/lib/python3.5/site-packages/django/db/backends/sqlite3/base.py", line 337, in execute
    return Database.Cursor.execute(self, query, params)
sqlite3.OperationalError: no such table: django_session

The above exception was the direct cause of the following exception:

Traceback (most recent call last):
  File "/home/django/.virtualenvs/edc-pharma/lib/python3.5/site-packages/django/core/handlers/exception.py", line 39, in inner
    response = get_response(request)
  File "/home/django/.virtualenvs/edc-pharma/lib/python3.5/site-packages/django/utils/deprecation.py", line 133, in __call__
    response = self.get_response(request)
  File "/home/django/.virtualenvs/edc-pharma/lib/python3.5/site-packages/django/core/handlers/exception.py", line 41, in inner
    response = response_for_exception(request, exc)
  File "/home/django/.virtualenvs/edc-pharma/lib/python3.5/site-packages/django/core/handlers/exception.py", line 86, in response_for_exception
    response = handle_uncaught_exception(request, get_resolver(get_urlconf()), sys.exc_info())
  File "/home/django/.virtualenvs/edc-pharma/lib/python3.5/site-packages/django/core/handlers/exception.py", line 128, in handle_uncaught_exception
    return debug.technical_500_response(request, *exc_info)
  File "/home/django/.virtualenvs/edc-pharma/lib/python3.5/site-packages/django/views/debug.py", line 84, in technical_500_response
    html = reporter.get_traceback_html()
  File "/home/django/.virtualenvs/edc-pharma/lib/python3.5/site-packages/django/views/debug.py", line 317, in get_traceback_html
    return t.render(c)
  File "/home/django/.virtualenvs/edc-pharma/lib/python3.5/site-packages/django/template/base.py", line 208, in render
    return self._render(context)
  File "/home/django/.virtualenvs/edc-pharma/lib/python3.5/site-packages/django/template/base.py", line 199, in _render
    return self.nodelist.render(context)
  File "/home/django/.virtualenvs/edc-pharma/lib/python3.5/site-packages/django/template/base.py", line 994, in render
    bit = node.render_annotated(context)
  File "/home/django/.virtualenvs/edc-pharma/lib/python3.5/site-packages/django/template/base.py", line 961, in render_annotated
    return self.render(context)
  File "/home/django/.virtualenvs/edc-pharma/lib/python3.5/site-packages/django/template/defaulttags.py", line 315, in render
    return nodelist.render(context)
  File "/home/django/.virtualenvs/edc-pharma/lib/python3.5/site-packages/django/template/base.py", line 994, in render
    bit = node.render_annotated(context)
  File "/home/django/.virtualenvs/edc-pharma/lib/python3.5/site-packages/django/template/base.py", line 961, in render_annotated
    return self.render(context)
  File "/home/django/.virtualenvs/edc-pharma/lib/python3.5/site-packages/django/template/defaulttags.py", line 314, in render
    if match:
  File "/home/django/.virtualenvs/edc-pharma/lib/python3.5/site-packages/django/utils/functional.py", line 234, in inner
    self._setup()
  File "/home/django/.virtualenvs/edc-pharma/lib/python3.5/site-packages/django/utils/functional.py", line 380, in _setup
    self._wrapped = self._setupfunc()
  File "/home/django/.virtualenvs/edc-pharma/lib/python3.5/site-packages/django/contrib/auth/middleware.py", line 24, in <lambda>
    request.user = SimpleLazyObject(lambda: get_user(request))
  File "/home/django/.virtualenvs/edc-pharma/lib/python3.5/site-packages/django/contrib/auth/middleware.py", line 12, in get_user
    request._cached_user = auth.get_user(request)
  File "/home/django/.virtualenvs/edc-pharma/lib/python3.5/site-packages/django/contrib/auth/__init__.py", line 180, in get_user
    user_id = _get_user_session_key(request)
  File "/home/django/.virtualenvs/edc-pharma/lib/python3.5/site-packages/django/contrib/auth/__init__.py", line 59, in _get_user_session_key
    return get_user_model()._meta.pk.to_python(request.session[SESSION_KEY])
  File "/home/django/.virtualenvs/edc-pharma/lib/python3.5/site-packages/django/contrib/sessions/backends/base.py", line 57, in __getitem__
    return self._session[key]
  File "/home/django/.virtualenvs/edc-pharma/lib/python3.5/site-packages/django/contrib/sessions/backends/base.py", line 207, in _get_session
    self._session_cache = self.load()
  File "/home/django/.virtualenvs/edc-pharma/lib/python3.5/site-packages/django/contrib/sessions/backends/db.py", line 35, in load
    expire_date__gt=timezone.now()
  File "/home/django/.virtualenvs/edc-pharma/lib/python3.5/site-packages/django/db/models/manager.py", line 85, in manager_method
    return getattr(self.get_queryset(), name)(*args, **kwargs)
  File "/home/django/.virtualenvs/edc-pharma/lib/python3.5/site-packages/django/db/models/query.py", line 379, in get
    num = len(clone)
  File "/home/django/.virtualenvs/edc-pharma/lib/python3.5/site-packages/django/db/models/query.py", line 238, in __len__
    self._fetch_all()
  File "/home/django/.virtualenvs/edc-pharma/lib/python3.5/site-packages/django/db/models/query.py", line 1087, in _fetch_all
    self._result_cache = list(self.iterator())
  File "/home/django/.virtualenvs/edc-pharma/lib/python3.5/site-packages/django/db/models/query.py", line 54, in __iter__
    results = compiler.execute_sql()
  File "/home/django/.virtualenvs/edc-pharma/lib/python3.5/site-packages/django/db/models/sql/compiler.py", line 835, in execute_sql
    cursor.execute(sql, params)
  File "/home/django/.virtualenvs/edc-pharma/lib/python3.5/site-packages/django/db/backends/utils.py", line 79, in execute
    return super(CursorDebugWrapper, self).execute(sql, params)
  File "/home/django/.virtualenvs/edc-pharma/lib/python3.5/site-packages/django/db/backends/utils.py", line 64, in execute
    return self.cursor.execute(sql, params)
  File "/home/django/.virtualenvs/edc-pharma/lib/python3.5/site-packages/django/db/utils.py", line 94, in __exit__
    six.reraise(dj_exc_type, dj_exc_value, traceback)
  File "/home/django/.virtualenvs/edc-pharma/lib/python3.5/site-packages/django/utils/six.py", line 685, in reraise
    raise value.with_traceback(tb)
  File "/home/django/.virtualenvs/edc-pharma/lib/python3.5/site-packages/django/db/backends/utils.py", line 64, in execute
    return self.cursor.execute(sql, params)
  File "/home/django/.virtualenvs/edc-pharma/lib/python3.5/site-packages/django/db/backends/sqlite3/base.py", line 337, in execute
    return Database.Cursor.execute(self, query, params)
django.db.utils.OperationalError: no such table: django_session

During handling of the above exception, another exception occurred:

Traceback (most recent call last):
  File "/home/django/.virtualenvs/edc-pharma/lib/python3.5/site-packages/django/contrib/sessions/backends/base.py", line 202, in _get_session
    return self._session_cache
AttributeError: 'SessionStore' object has no attribute '_session_cache'

During handling of the above exception, another exception occurred:

Traceback (most recent call last):
  File "/home/django/.virtualenvs/edc-pharma/lib/python3.5/site-packages/django/db/backends/utils.py", line 64, in execute
    return self.cursor.execute(sql, params)
  File "/home/django/.virtualenvs/edc-pharma/lib/python3.5/site-packages/django/db/backends/sqlite3/base.py", line 337, in execute
    return Database.Cursor.execute(self, query, params)
sqlite3.OperationalError: no such table: django_session

The above exception was the direct cause of the following exception:

Traceback (most recent call last):
  File "/home/django/.virtualenvs/edc-pharma/lib/python3.5/site-packages/django/core/handlers/exception.py", line 39, in inner
    response = get_response(request)
  File "/home/django/.virtualenvs/edc-pharma/lib/python3.5/site-packages/django/utils/deprecation.py", line 133, in __call__
    response = self.get_response(request)
  File "/home/django/.virtualenvs/edc-pharma/lib/python3.5/site-packages/django/core/handlers/exception.py", line 41, in inner
    response = response_for_exception(request, exc)
  File "/home/django/.virtualenvs/edc-pharma/lib/python3.5/site-packages/django/core/handlers/exception.py", line 86, in response_for_exception
    response = handle_uncaught_exception(request, get_resolver(get_urlconf()), sys.exc_info())
  File "/home/django/.virtualenvs/edc-pharma/lib/python3.5/site-packages/django/core/handlers/exception.py", line 128, in handle_uncaught_exception
    return debug.technical_500_response(request, *exc_info)
  File "/home/django/.virtualenvs/edc-pharma/lib/python3.5/site-packages/django/views/debug.py", line 84, in technical_500_response
    html = reporter.get_traceback_html()
  File "/home/django/.virtualenvs/edc-pharma/lib/python3.5/site-packages/django/views/debug.py", line 317, in get_traceback_html
    return t.render(c)
  File "/home/django/.virtualenvs/edc-pharma/lib/python3.5/site-packages/django/template/base.py", line 208, in render
    return self._render(context)
  File "/home/django/.virtualenvs/edc-pharma/lib/python3.5/site-packages/django/template/base.py", line 199, in _render
    return self.nodelist.render(context)
  File "/home/django/.virtualenvs/edc-pharma/lib/python3.5/site-packages/django/template/base.py", line 994, in render
    bit = node.render_annotated(context)
  File "/home/django/.virtualenvs/edc-pharma/lib/python3.5/site-packages/django/template/base.py", line 961, in render_annotated
    return self.render(context)
  File "/home/django/.virtualenvs/edc-pharma/lib/python3.5/site-packages/django/template/defaulttags.py", line 315, in render
    return nodelist.render(context)
  File "/home/django/.virtualenvs/edc-pharma/lib/python3.5/site-packages/django/template/base.py", line 994, in render
    bit = node.render_annotated(context)
  File "/home/django/.virtualenvs/edc-pharma/lib/python3.5/site-packages/django/template/base.py", line 961, in render_annotated
    return self.render(context)
  File "/home/django/.virtualenvs/edc-pharma/lib/python3.5/site-packages/django/template/defaulttags.py", line 314, in render
    if match:
  File "/home/django/.virtualenvs/edc-pharma/lib/python3.5/site-packages/django/utils/functional.py", line 234, in inner
    self._setup()
  File "/home/django/.virtualenvs/edc-pharma/lib/python3.5/site-packages/django/utils/functional.py", line 380, in _setup
    self._wrapped = self._setupfunc()
  File "/home/django/.virtualenvs/edc-pharma/lib/python3.5/site-packages/django/contrib/auth/middleware.py", line 24, in <lambda>
    request.user = SimpleLazyObject(lambda: get_user(request))
  File "/home/django/.virtualenvs/edc-pharma/lib/python3.5/site-packages/django/contrib/auth/middleware.py", line 12, in get_user
    request._cached_user = auth.get_user(request)
  File "/home/django/.virtualenvs/edc-pharma/lib/python3.5/site-packages/django/contrib/auth/__init__.py", line 180, in get_user
    user_id = _get_user_session_key(request)
  File "/home/django/.virtualenvs/edc-pharma/lib/python3.5/site-packages/django/contrib/auth/__init__.py", line 59, in _get_user_session_key
    return get_user_model()._meta.pk.to_python(request.session[SESSION_KEY])
  File "/home/django/.virtualenvs/edc-pharma/lib/python3.5/site-packages/django/contrib/sessions/backends/base.py", line 57, in __getitem__
    return self._session[key]
  File "/home/django/.virtualenvs/edc-pharma/lib/python3.5/site-packages/django/contrib/sessions/backends/base.py", line 207, in _get_session
    self._session_cache = self.load()
  File "/home/django/.virtualenvs/edc-pharma/lib/python3.5/site-packages/django/contrib/sessions/backends/db.py", line 35, in load
    expire_date__gt=timezone.now()
  File "/home/django/.virtualenvs/edc-pharma/lib/python3.5/site-packages/django/db/models/manager.py", line 85, in manager_method
    return getattr(self.get_queryset(), name)(*args, **kwargs)
  File "/home/django/.virtualenvs/edc-pharma/lib/python3.5/site-packages/django/db/models/query.py", line 379, in get
    num = len(clone)
  File "/home/django/.virtualenvs/edc-pharma/lib/python3.5/site-packages/django/db/models/query.py", line 238, in __len__
    self._fetch_all()
  File "/home/django/.virtualenvs/edc-pharma/lib/python3.5/site-packages/django/db/models/query.py", line 1087, in _fetch_all
    self._result_cache = list(self.iterator())
  File "/home/django/.virtualenvs/edc-pharma/lib/python3.5/site-packages/django/db/models/query.py", line 54, in __iter__
    results = compiler.execute_sql()
  File "/home/django/.virtualenvs/edc-pharma/lib/python3.5/site-packages/django/db/models/sql/compiler.py", line 835, in execute_sql
    cursor.execute(sql, params)
  File "/home/django/.virtualenvs/edc-pharma/lib/python3.5/site-packages/django/db/backends/utils.py", line 79, in execute
    return super(CursorDebugWrapper, self).execute(sql, params)
  File "/home/django/.virtualenvs/edc-pharma/lib/python3.5/site-packages/django/db/backends/utils.py", line 64, in execute
    return self.cursor.execute(sql, params)
  File "/home/django/.virtualenvs/edc-pharma/lib/python3.5/site-packages/django/db/utils.py", line 94, in __exit__
    six.reraise(dj_exc_type, dj_exc_value, traceback)
  File "/home/django/.virtualenvs/edc-pharma/lib/python3.5/site-packages/django/utils/six.py", line 685, in reraise
    raise value.with_traceback(tb)
  File "/home/django/.virtualenvs/edc-pharma/lib/python3.5/site-packages/django/db/backends/utils.py", line 64, in execute
    return self.cursor.execute(sql, params)
  File "/home/django/.virtualenvs/edc-pharma/lib/python3.5/site-packages/django/db/backends/sqlite3/base.py", line 337, in execute
    return Database.Cursor.execute(self, query, params)
django.db.utils.OperationalError: no such table: django_session

During handling of the above exception, another exception occurred:

Traceback (most recent call last):
  File "/home/django/.virtualenvs/edc-pharma/lib/python3.5/site-packages/django/contrib/sessions/backends/base.py", line 202, in _get_session
    return self._session_cache
AttributeError: 'SessionStore' object has no attribute '_session_cache'

During handling of the above exception, another exception occurred:

Traceback (most recent call last):
  File "/home/django/.virtualenvs/edc-pharma/lib/python3.5/site-packages/django/db/backends/utils.py", line 64, in execute
    return self.cursor.execute(sql, params)
  File "/home/django/.virtualenvs/edc-pharma/lib/python3.5/site-packages/django/db/backends/sqlite3/base.py", line 337, in execute
    return Database.Cursor.execute(self, query, params)
sqlite3.OperationalError: no such table: django_session

The above exception was the direct cause of the following exception:

Traceback (most recent call last):
  File "/home/django/.virtualenvs/edc-pharma/lib/python3.5/site-packages/django/core/handlers/exception.py", line 39, in inner
    response = get_response(request)
  File "/home/django/.virtualenvs/edc-pharma/lib/python3.5/site-packages/django/utils/deprecation.py", line 133, in __call__
    response = self.get_response(request)
  File "/home/django/.virtualenvs/edc-pharma/lib/python3.5/site-packages/django/core/handlers/exception.py", line 41, in inner
    response = response_for_exception(request, exc)
  File "/home/django/.virtualenvs/edc-pharma/lib/python3.5/site-packages/django/core/handlers/exception.py", line 86, in response_for_exception
    response = handle_uncaught_exception(request, get_resolver(get_urlconf()), sys.exc_info())
  File "/home/django/.virtualenvs/edc-pharma/lib/python3.5/site-packages/django/core/handlers/exception.py", line 128, in handle_uncaught_exception
    return debug.technical_500_response(request, *exc_info)
  File "/home/django/.virtualenvs/edc-pharma/lib/python3.5/site-packages/django/views/debug.py", line 84, in technical_500_response
    html = reporter.get_traceback_html()
  File "/home/django/.virtualenvs/edc-pharma/lib/python3.5/site-packages/django/views/debug.py", line 317, in get_traceback_html
    return t.render(c)
  File "/home/django/.virtualenvs/edc-pharma/lib/python3.5/site-packages/django/template/base.py", line 208, in render
    return self._render(context)
  File "/home/django/.virtualenvs/edc-pharma/lib/python3.5/site-packages/django/template/base.py", line 199, in _render
    return self.nodelist.render(context)
  File "/home/django/.virtualenvs/edc-pharma/lib/python3.5/site-packages/django/template/base.py", line 994, in render
    bit = node.render_annotated(context)
  File "/home/django/.virtualenvs/edc-pharma/lib/python3.5/site-packages/django/template/base.py", line 961, in render_annotated
    return self.render(context)
  File "/home/django/.virtualenvs/edc-pharma/lib/python3.5/site-packages/django/template/defaulttags.py", line 315, in render
    return nodelist.render(context)
  File "/home/django/.virtualenvs/edc-pharma/lib/python3.5/site-packages/django/template/base.py", line 994, in render
    bit = node.render_annotated(context)
  File "/home/django/.virtualenvs/edc-pharma/lib/python3.5/site-packages/django/template/base.py", line 961, in render_annotated
    return self.render(context)
  File "/home/django/.virtualenvs/edc-pharma/lib/python3.5/site-packages/django/template/defaulttags.py", line 314, in render
    if match:
  File "/home/django/.virtualenvs/edc-pharma/lib/python3.5/site-packages/django/utils/functional.py", line 234, in inner
    self._setup()
  File "/home/django/.virtualenvs/edc-pharma/lib/python3.5/site-packages/django/utils/functional.py", line 380, in _setup
    self._wrapped = self._setupfunc()
  File "/home/django/.virtualenvs/edc-pharma/lib/python3.5/site-packages/django/contrib/auth/middleware.py", line 24, in <lambda>
    request.user = SimpleLazyObject(lambda: get_user(request))
  File "/home/django/.virtualenvs/edc-pharma/lib/python3.5/site-packages/django/contrib/auth/middleware.py", line 12, in get_user
    request._cached_user = auth.get_user(request)
  File "/home/django/.virtualenvs/edc-pharma/lib/python3.5/site-packages/django/contrib/auth/__init__.py", line 180, in get_user
    user_id = _get_user_session_key(request)
  File "/home/django/.virtualenvs/edc-pharma/lib/python3.5/site-packages/django/contrib/auth/__init__.py", line 59, in _get_user_session_key
    return get_user_model()._meta.pk.to_python(request.session[SESSION_KEY])
  File "/home/django/.virtualenvs/edc-pharma/lib/python3.5/site-packages/django/contrib/sessions/backends/base.py", line 57, in __getitem__
    return self._session[key]
  File "/home/django/.virtualenvs/edc-pharma/lib/python3.5/site-packages/django/contrib/sessions/backends/base.py", line 207, in _get_session
    self._session_cache = self.load()
  File "/home/django/.virtualenvs/edc-pharma/lib/python3.5/site-packages/django/contrib/sessions/backends/db.py", line 35, in load
    expire_date__gt=timezone.now()
  File "/home/django/.virtualenvs/edc-pharma/lib/python3.5/site-packages/django/db/models/manager.py", line 85, in manager_method
    return getattr(self.get_queryset(), name)(*args, **kwargs)
  File "/home/django/.virtualenvs/edc-pharma/lib/python3.5/site-packages/django/db/models/query.py", line 379, in get
    num = len(clone)
  File "/home/django/.virtualenvs/edc-pharma/lib/python3.5/site-packages/django/db/models/query.py", line 238, in __len__
    self._fetch_all()
  File "/home/django/.virtualenvs/edc-pharma/lib/python3.5/site-packages/django/db/models/query.py", line 1087, in _fetch_all
    self._result_cache = list(self.iterator())
  File "/home/django/.virtualenvs/edc-pharma/lib/python3.5/site-packages/django/db/models/query.py", line 54, in __iter__
    results = compiler.execute_sql()
  File "/home/django/.virtualenvs/edc-pharma/lib/python3.5/site-packages/django/db/models/sql/compiler.py", line 835, in execute_sql
    cursor.execute(sql, params)
  File "/home/django/.virtualenvs/edc-pharma/lib/python3.5/site-packages/django/db/backends/utils.py", line 79, in execute
    return super(CursorDebugWrapper, self).execute(sql, params)
  File "/home/django/.virtualenvs/edc-pharma/lib/python3.5/site-packages/django/db/backends/utils.py", line 64, in execute
    return self.cursor.execute(sql, params)
  File "/home/django/.virtualenvs/edc-pharma/lib/python3.5/site-packages/django/db/utils.py", line 94, in __exit__
    six.reraise(dj_exc_type, dj_exc_value, traceback)
  File "/home/django/.virtualenvs/edc-pharma/lib/python3.5/site-packages/django/utils/six.py", line 685, in reraise
    raise value.with_traceback(tb)
  File "/home/django/.virtualenvs/edc-pharma/lib/python3.5/site-packages/django/db/backends/utils.py", line 64, in execute
    return self.cursor.execute(sql, params)
  File "/home/django/.virtualenvs/edc-pharma/lib/python3.5/site-packages/django/db/backends/sqlite3/base.py", line 337, in execute
    return Database.Cursor.execute(self, query, params)
django.db.utils.OperationalError: no such table: django_session

During handling of the above exception, another exception occurred:

Traceback (most recent call last):
  File "/home/django/.virtualenvs/edc-pharma/lib/python3.5/site-packages/django/contrib/sessions/backends/base.py", line 202, in _get_session
    return self._session_cache
AttributeError: 'SessionStore' object has no attribute '_session_cache'

During handling of the above exception, another exception occurred:

Traceback (most recent call last):
  File "/home/django/.virtualenvs/edc-pharma/lib/python3.5/site-packages/django/db/backends/utils.py", line 64, in execute
    return self.cursor.execute(sql, params)
  File "/home/django/.virtualenvs/edc-pharma/lib/python3.5/site-packages/django/db/backends/sqlite3/base.py", line 337, in execute
    return Database.Cursor.execute(self, query, params)
sqlite3.OperationalError: no such table: django_session

The above exception was the direct cause of the following exception:

Traceback (most recent call last):
  File "/home/django/.virtualenvs/edc-pharma/lib/python3.5/site-packages/gunicorn/workers/sync.py", line 135, in handle
    self.handle_request(listener, req, client, addr)
  File "/home/django/.virtualenvs/edc-pharma/lib/python3.5/site-packages/gunicorn/workers/sync.py", line 176, in handle_request
    respiter = self.wsgi(environ, resp.start_response)
  File "/home/django/.virtualenvs/edc-pharma/lib/python3.5/site-packages/django/core/handlers/wsgi.py", line 170, in __call__
    response = self.get_response(request)
  File "/home/django/.virtualenvs/edc-pharma/lib/python3.5/site-packages/django/core/handlers/base.py", line 124, in get_response
    response = self._middleware_chain(request)
  File "/home/django/.virtualenvs/edc-pharma/lib/python3.5/site-packages/django/core/handlers/exception.py", line 41, in inner
    response = response_for_exception(request, exc)
  File "/home/django/.virtualenvs/edc-pharma/lib/python3.5/site-packages/django/core/handlers/exception.py", line 86, in response_for_exception
    response = handle_uncaught_exception(request, get_resolver(get_urlconf()), sys.exc_info())
  File "/home/django/.virtualenvs/edc-pharma/lib/python3.5/site-packages/django/core/handlers/exception.py", line 128, in handle_uncaught_exception
    return debug.technical_500_response(request, *exc_info)
  File "/home/django/.virtualenvs/edc-pharma/lib/python3.5/site-packages/django/views/debug.py", line 84, in technical_500_response
    html = reporter.get_traceback_html()
  File "/home/django/.virtualenvs/edc-pharma/lib/python3.5/site-packages/django/views/debug.py", line 317, in get_traceback_html
    return t.render(c)
  File "/home/django/.virtualenvs/edc-pharma/lib/python3.5/site-packages/django/template/base.py", line 208, in render
    return self._render(context)
  File "/home/django/.virtualenvs/edc-pharma/lib/python3.5/site-packages/django/template/base.py", line 199, in _render
    return self.nodelist.render(context)
  File "/home/django/.virtualenvs/edc-pharma/lib/python3.5/site-packages/django/template/base.py", line 994, in render
    bit = node.render_annotated(context)
  File "/home/django/.virtualenvs/edc-pharma/lib/python3.5/site-packages/django/template/base.py", line 961, in render_annotated
    return self.render(context)
  File "/home/django/.virtualenvs/edc-pharma/lib/python3.5/site-packages/django/template/defaulttags.py", line 315, in render
    return nodelist.render(context)
  File "/home/django/.virtualenvs/edc-pharma/lib/python3.5/site-packages/django/template/base.py", line 994, in render
    bit = node.render_annotated(context)
  File "/home/django/.virtualenvs/edc-pharma/lib/python3.5/site-packages/django/template/base.py", line 961, in render_annotated
    return self.render(context)
  File "/home/django/.virtualenvs/edc-pharma/lib/python3.5/site-packages/django/template/defaulttags.py", line 314, in render
    if match:
  File "/home/django/.virtualenvs/edc-pharma/lib/python3.5/site-packages/django/utils/functional.py", line 234, in inner
    self._setup()
  File "/home/django/.virtualenvs/edc-pharma/lib/python3.5/site-packages/django/utils/functional.py", line 380, in _setup
    self._wrapped = self._setupfunc()
  File "/home/django/.virtualenvs/edc-pharma/lib/python3.5/site-packages/django/contrib/auth/middleware.py", line 24, in <lambda>
    request.user = SimpleLazyObject(lambda: get_user(request))
  File "/home/django/.virtualenvs/edc-pharma/lib/python3.5/site-packages/django/contrib/auth/middleware.py", line 12, in get_user
    request._cached_user = auth.get_user(request)
  File "/home/django/.virtualenvs/edc-pharma/lib/python3.5/site-packages/django/contrib/auth/__init__.py", line 180, in get_user
    user_id = _get_user_session_key(request)
  File "/home/django/.virtualenvs/edc-pharma/lib/python3.5/site-packages/django/contrib/auth/__init__.py", line 59, in _get_user_session_key
    return get_user_model()._meta.pk.to_python(request.session[SESSION_KEY])
  File "/home/django/.virtualenvs/edc-pharma/lib/python3.5/site-packages/django/contrib/sessions/backends/base.py", line 57, in __getitem__
    return self._session[key]
  File "/home/django/.virtualenvs/edc-pharma/lib/python3.5/site-packages/django/contrib/sessions/backends/base.py", line 207, in _get_session
    self._session_cache = self.load()
  File "/home/django/.virtualenvs/edc-pharma/lib/python3.5/site-packages/django/contrib/sessions/backends/db.py", line 35, in load
    expire_date__gt=timezone.now()
  File "/home/django/.virtualenvs/edc-pharma/lib/python3.5/site-packages/django/db/models/manager.py", line 85, in manager_method
    return getattr(self.get_queryset(), name)(*args, **kwargs)
  File "/home/django/.virtualenvs/edc-pharma/lib/python3.5/site-packages/django/db/models/query.py", line 379, in get
    num = len(clone)
  File "/home/django/.virtualenvs/edc-pharma/lib/python3.5/site-packages/django/db/models/query.py", line 238, in __len__
    self._fetch_all()
  File "/home/django/.virtualenvs/edc-pharma/lib/python3.5/site-packages/django/db/models/query.py", line 1087, in _fetch_all
    self._result_cache = list(self.iterator())
  File "/home/django/.virtualenvs/edc-pharma/lib/python3.5/site-packages/django/db/models/query.py", line 54, in __iter__
    results = compiler.execute_sql()
  File "/home/django/.virtualenvs/edc-pharma/lib/python3.5/site-packages/django/db/models/sql/compiler.py", line 835, in execute_sql
    cursor.execute(sql, params)
  File "/home/django/.virtualenvs/edc-pharma/lib/python3.5/site-packages/django/db/backends/utils.py", line 79, in execute
    return super(CursorDebugWrapper, self).execute(sql, params)
  File "/home/django/.virtualenvs/edc-pharma/lib/python3.5/site-packages/django/db/backends/utils.py", line 64, in execute
    return self.cursor.execute(sql, params)
  File "/home/django/.virtualenvs/edc-pharma/lib/python3.5/site-packages/django/db/utils.py", line 94, in __exit__
    six.reraise(dj_exc_type, dj_exc_value, traceback)
  File "/home/django/.virtualenvs/edc-pharma/lib/python3.5/site-packages/django/utils/six.py", line 685, in reraise
    raise value.with_traceback(tb)
  File "/home/django/.virtualenvs/edc-pharma/lib/python3.5/site-packages/django/db/backends/utils.py", line 64, in execute
    return self.cursor.execute(sql, params)
  File "/home/django/.virtualenvs/edc-pharma/lib/python3.5/site-packages/django/db/backends/sqlite3/base.py", line 337, in execute
    return Database.Cursor.execute(self, query, params)
django.db.utils.OperationalError: no such table: django_session
[2016-11-03 13:11:25 +0200] [10754] [INFO] Handling signal: term
[2016-11-03 13:11:25 +0200] [10757] [INFO] Worker exiting (pid: 10757)
[2016-11-03 13:11:25 +0200] [10754] [INFO] Shutting down: Master
[2016-11-03 13:11:27 +0200] [10845] [DEBUG] Current configuration:
  worker_int: <function WorkerInt.worker_int at 0x7f1a8ee39e18>
  access_log_format: %(h)s %(l)s %(u)s %(t)s "%(r)s" %(s)s %(b)s "%(f)s" "%(a)s"
  workers: 1
  limit_request_field_size: 8190
  worker_abort: <function WorkerAbort.worker_abort at 0x7f1a8ee43048>
  daemon: True
  secure_scheme_headers: {'X-FORWARDED-PROTO': 'https', 'X-FORWARDED-PROTOCOL': 'ssl', 'X-FORWARDED-SSL': 'on'}
  spew: False
  accesslog: /home/django/source/edc-pharma/logs/gunicorn-access.log
  loglevel: debug
  capture_output: False
  logconfig: None
  syslog_prefix: None
  statsd_host: None
  worker_class: sync
  pidfile: logs/gunicorn.pid
  user: 1004
  umask: 0
  forwarded_allow_ips: ['127.0.0.1']
  proxy_protocol: False
  when_ready: <function WhenReady.when_ready at 0x7f1a8ee397b8>
  worker_exit: <function WorkerExit.worker_exit at 0x7f1a8ee43620>
  syslog_addr: udp://localhost:514
  syslog: False
  backlog: 2048
  pre_fork: <function Prefork.pre_fork at 0x7f1a8ee39950>
  max_requests: 0
  timeout: 30
  paste: None
  keyfile: None
  config: gunicorn.conf.py
  on_starting: <function OnStarting.on_starting at 0x7f1a8ee39488>
  post_worker_init: <function PostWorkerInit.post_worker_init at 0x7f1a8ee39c80>
  logger_class: gunicorn.glogging.Logger
  post_fork: <function Postfork.post_fork at 0x7f1a8ee39ae8>
  suppress_ragged_eofs: True
  proc_name: None
  certfile: None
  on_reload: <function OnReload.on_reload at 0x7f1a8ee39620>
  threads: 1
  graceful_timeout: 30
  preload_app: False
  worker_connections: 1000
  pre_request: <function PreRequest.pre_request at 0x7f1a8ee43378>
  nworkers_changed: <function NumWorkersChanged.nworkers_changed at 0x7f1a8ee437b8>
  raw_env: []
  cert_reqs: 0
  do_handshake_on_connect: False
  errorlog: /home/django/source/edc-pharma/logs/gunicorn-error.log
  statsd_prefix: 
  pre_exec: <function PreExec.pre_exec at 0x7f1a8ee431e0>
  limit_request_line: 4094
  limit_request_fields: 100
  on_exit: <function OnExit.on_exit at 0x7f1a8ee43950>
  chdir: /home/django/source/edc-pharma
  tmp_upload_dir: None
  max_requests_jitter: 0
  reload: False
  worker_tmp_dir: None
  ssl_version: 3
  ciphers: TLSv1
  enable_stdio_inheritance: False
  django_settings: None
  syslog_facility: user
  post_request: <function PostRequest.post_request at 0x7f1a8ee43488>
  default_proc_name: edc_pharma.wsgi
  check_config: False
  sendfile: None
  group: 1004
  pythonpath: None
  proxy_allow_ips: ['127.0.0.1']
  keepalive: 2
  ca_certs: None
  bind: ['127.0.0.1:9000']
[2016-11-03 13:11:27 +0200] [10845] [INFO] Starting gunicorn 19.6.0
[2016-11-03 13:11:27 +0200] [10845] [DEBUG] Arbiter booted
[2016-11-03 13:11:27 +0200] [10845] [INFO] Listening at: http://127.0.0.1:9000 (10845)
[2016-11-03 13:11:27 +0200] [10845] [INFO] Using worker: sync
[2016-11-03 13:11:27 +0200] [10848] [INFO] Booting worker with pid: 10848
[2016-11-03 13:11:27 +0200] [10845] [DEBUG] 1 workers
[2016-11-03 13:11:27 +0200] [10848] [ERROR] Exception in worker process
Traceback (most recent call last):
  File "/home/django/.virtualenvs/edc-pharma/lib/python3.5/site-packages/gunicorn/arbiter.py", line 557, in spawn_worker
    worker.init_process()
  File "/home/django/.virtualenvs/edc-pharma/lib/python3.5/site-packages/gunicorn/workers/base.py", line 126, in init_process
    self.load_wsgi()
  File "/home/django/.virtualenvs/edc-pharma/lib/python3.5/site-packages/gunicorn/workers/base.py", line 136, in load_wsgi
    self.wsgi = self.app.wsgi()
  File "/home/django/.virtualenvs/edc-pharma/lib/python3.5/site-packages/gunicorn/app/base.py", line 67, in wsgi
    self.callable = self.load()
  File "/home/django/.virtualenvs/edc-pharma/lib/python3.5/site-packages/gunicorn/app/wsgiapp.py", line 65, in load
    return self.load_wsgiapp()
  File "/home/django/.virtualenvs/edc-pharma/lib/python3.5/site-packages/gunicorn/app/wsgiapp.py", line 52, in load_wsgiapp
    return util.import_app(self.app_uri)
  File "/home/django/.virtualenvs/edc-pharma/lib/python3.5/site-packages/gunicorn/util.py", line 357, in import_app
    __import__(module)
  File "/home/django/source/edc-pharma/edc_pharma/wsgi.py", line 16, in <module>
    application = get_wsgi_application()
  File "/home/django/.virtualenvs/edc-pharma/lib/python3.5/site-packages/django/core/wsgi.py", line 13, in get_wsgi_application
    django.setup(set_prefix=False)
  File "/home/django/.virtualenvs/edc-pharma/lib/python3.5/site-packages/django/__init__.py", line 22, in setup
    configure_logging(settings.LOGGING_CONFIG, settings.LOGGING)
  File "/home/django/.virtualenvs/edc-pharma/lib/python3.5/site-packages/django/conf/__init__.py", line 53, in __getattr__
    self._setup(name)
  File "/home/django/.virtualenvs/edc-pharma/lib/python3.5/site-packages/django/conf/__init__.py", line 41, in _setup
    self._wrapped = Settings(settings_module)
  File "/home/django/.virtualenvs/edc-pharma/lib/python3.5/site-packages/django/conf/__init__.py", line 97, in __init__
    mod = importlib.import_module(self.SETTINGS_MODULE)
  File "/home/django/.virtualenvs/edc-pharma/lib/python3.5/importlib/__init__.py", line 126, in import_module
    return _bootstrap._gcd_import(name[level:], package, level)
  File "/home/django/source/edc-pharma/edc_pharma/settings.py", line 93
    DATABASES = {
              ^
SyntaxError: invalid syntax
[2016-11-03 13:11:27 +0200] [10848] [INFO] Worker exiting (pid: 10848)
[2016-11-03 13:11:28 +0200] [10845] [INFO] Shutting down: Master
[2016-11-03 13:11:28 +0200] [10845] [INFO] Reason: Worker failed to boot.
[2016-11-03 13:14:00 +0200] [10867] [DEBUG] Current configuration:
  limit_request_line: 4094
  pre_request: <function PreRequest.pre_request at 0x7f6720980378>
  config: gunicorn.conf.py
  tmp_upload_dir: None
  worker_exit: <function WorkerExit.worker_exit at 0x7f6720980620>
  ca_certs: None
  proxy_protocol: False
  accesslog: /home/django/source/edc-pharma/logs/gunicorn-access.log
  logger_class: gunicorn.glogging.Logger
  syslog_addr: udp://localhost:514
  syslog_facility: user
  enable_stdio_inheritance: False
  worker_class: sync
  bind: ['127.0.0.1:9000']
  backlog: 2048
  daemon: True
  raw_env: []
  forwarded_allow_ips: ['127.0.0.1']
  pre_exec: <function PreExec.pre_exec at 0x7f67209801e0>
  post_request: <function PostRequest.post_request at 0x7f6720980488>
  statsd_prefix: 
  worker_connections: 1000
  max_requests: 0
  sendfile: None
  keyfile: None
  graceful_timeout: 30
  post_fork: <function Postfork.post_fork at 0x7f6720976ae8>
  proxy_allow_ips: ['127.0.0.1']
  worker_abort: <function WorkerAbort.worker_abort at 0x7f6720980048>
  umask: 0
  django_settings: None
  access_log_format: %(h)s %(l)s %(u)s %(t)s "%(r)s" %(s)s %(b)s "%(f)s" "%(a)s"
  syslog_prefix: None
  certfile: None
  nworkers_changed: <function NumWorkersChanged.nworkers_changed at 0x7f67209807b8>
  threads: 1
  on_exit: <function OnExit.on_exit at 0x7f6720980950>
  do_handshake_on_connect: False
  on_reload: <function OnReload.on_reload at 0x7f6720976620>
  check_config: False
  workers: 1
  limit_request_field_size: 8190
  suppress_ragged_eofs: True
  pre_fork: <function Prefork.pre_fork at 0x7f6720976950>
  group: 1004
  cert_reqs: 0
  preload_app: False
  chdir: /home/django/source/edc-pharma
  worker_tmp_dir: None
  user: 1004
  reload: False
  worker_int: <function WorkerInt.worker_int at 0x7f6720976e18>
  errorlog: /home/django/source/edc-pharma/logs/gunicorn-error.log
  logconfig: None
  on_starting: <function OnStarting.on_starting at 0x7f6720976488>
  capture_output: False
  syslog: False
  statsd_host: None
  limit_request_fields: 100
  proc_name: None
  pidfile: logs/gunicorn.pid
  secure_scheme_headers: {'X-FORWARDED-SSL': 'on', 'X-FORWARDED-PROTOCOL': 'ssl', 'X-FORWARDED-PROTO': 'https'}
  paste: None
  timeout: 30
  post_worker_init: <function PostWorkerInit.post_worker_init at 0x7f6720976c80>
  max_requests_jitter: 0
  pythonpath: None
  loglevel: debug
  ssl_version: 3
  ciphers: TLSv1
  keepalive: 2
  default_proc_name: edc_pharma.wsgi
  when_ready: <function WhenReady.when_ready at 0x7f67209767b8>
  spew: False
[2016-11-03 13:14:00 +0200] [10867] [INFO] Starting gunicorn 19.6.0
[2016-11-03 13:14:00 +0200] [10867] [DEBUG] Arbiter booted
[2016-11-03 13:14:00 +0200] [10867] [INFO] Listening at: http://127.0.0.1:9000 (10867)
[2016-11-03 13:14:00 +0200] [10867] [INFO] Using worker: sync
[2016-11-03 13:14:00 +0200] [10870] [INFO] Booting worker with pid: 10870
[2016-11-03 13:14:00 +0200] [10867] [DEBUG] 1 workers
[2016-11-03 13:14:00 +0200] [10870] [ERROR] Exception in worker process
Traceback (most recent call last):
  File "/home/django/.virtualenvs/edc-pharma/lib/python3.5/site-packages/gunicorn/arbiter.py", line 557, in spawn_worker
    worker.init_process()
  File "/home/django/.virtualenvs/edc-pharma/lib/python3.5/site-packages/gunicorn/workers/base.py", line 126, in init_process
    self.load_wsgi()
  File "/home/django/.virtualenvs/edc-pharma/lib/python3.5/site-packages/gunicorn/workers/base.py", line 136, in load_wsgi
    self.wsgi = self.app.wsgi()
  File "/home/django/.virtualenvs/edc-pharma/lib/python3.5/site-packages/gunicorn/app/base.py", line 67, in wsgi
    self.callable = self.load()
  File "/home/django/.virtualenvs/edc-pharma/lib/python3.5/site-packages/gunicorn/app/wsgiapp.py", line 65, in load
    return self.load_wsgiapp()
  File "/home/django/.virtualenvs/edc-pharma/lib/python3.5/site-packages/gunicorn/app/wsgiapp.py", line 52, in load_wsgiapp
    return util.import_app(self.app_uri)
  File "/home/django/.virtualenvs/edc-pharma/lib/python3.5/site-packages/gunicorn/util.py", line 357, in import_app
    __import__(module)
  File "/home/django/source/edc-pharma/edc_pharma/wsgi.py", line 16, in <module>
    application = get_wsgi_application()
  File "/home/django/.virtualenvs/edc-pharma/lib/python3.5/site-packages/django/core/wsgi.py", line 13, in get_wsgi_application
    django.setup(set_prefix=False)
  File "/home/django/.virtualenvs/edc-pharma/lib/python3.5/site-packages/django/__init__.py", line 22, in setup
    configure_logging(settings.LOGGING_CONFIG, settings.LOGGING)
  File "/home/django/.virtualenvs/edc-pharma/lib/python3.5/site-packages/django/conf/__init__.py", line 53, in __getattr__
    self._setup(name)
  File "/home/django/.virtualenvs/edc-pharma/lib/python3.5/site-packages/django/conf/__init__.py", line 41, in _setup
    self._wrapped = Settings(settings_module)
  File "/home/django/.virtualenvs/edc-pharma/lib/python3.5/site-packages/django/conf/__init__.py", line 97, in __init__
    mod = importlib.import_module(self.SETTINGS_MODULE)
  File "/home/django/.virtualenvs/edc-pharma/lib/python3.5/importlib/__init__.py", line 126, in import_module
    return _bootstrap._gcd_import(name[level:], package, level)
  File "/home/django/source/edc-pharma/edc_pharma/settings.py", line 95
    'NAME': 'banamotswe',
          ^
SyntaxError: invalid syntax
[2016-11-03 13:14:00 +0200] [10870] [INFO] Worker exiting (pid: 10870)
[2016-11-03 13:14:00 +0200] [10867] [INFO] Shutting down: Master
[2016-11-03 13:14:00 +0200] [10867] [INFO] Reason: Worker failed to boot.
[2016-11-03 13:14:35 +0200] [10889] [DEBUG] Current configuration:
  ciphers: TLSv1
  max_requests_jitter: 0
  do_handshake_on_connect: False
  statsd_host: None
  default_proc_name: edc_pharma.wsgi
  spew: False
  threads: 1
  worker_connections: 1000
  post_fork: <function Postfork.post_fork at 0x7f3c022f2ae8>
  worker_int: <function WorkerInt.worker_int at 0x7f3c022f2e18>
  pre_exec: <function PreExec.pre_exec at 0x7f3c022fc1e0>
  nworkers_changed: <function NumWorkersChanged.nworkers_changed at 0x7f3c022fc7b8>
  preload_app: False
  sendfile: None
  chdir: /home/django/source/edc-pharma
  statsd_prefix: 
  ca_certs: None
  on_reload: <function OnReload.on_reload at 0x7f3c022f2620>
  reload: False
  worker_exit: <function WorkerExit.worker_exit at 0x7f3c022fc620>
  errorlog: /home/django/source/edc-pharma/logs/gunicorn-error.log
  logger_class: gunicorn.glogging.Logger
  enable_stdio_inheritance: False
  group: 1004
  secure_scheme_headers: {'X-FORWARDED-SSL': 'on', 'X-FORWARDED-PROTOCOL': 'ssl', 'X-FORWARDED-PROTO': 'https'}
  forwarded_allow_ips: ['127.0.0.1']
  pythonpath: None
  paste: None
  keyfile: None
  max_requests: 0
  graceful_timeout: 30
  syslog_addr: udp://localhost:514
  suppress_ragged_eofs: True
  check_config: False
  pre_request: <function PreRequest.pre_request at 0x7f3c022fc378>
  bind: ['127.0.0.1:9000']
  certfile: None
  logconfig: None
  on_starting: <function OnStarting.on_starting at 0x7f3c022f2488>
  on_exit: <function OnExit.on_exit at 0x7f3c022fc950>
  config: gunicorn.conf.py
  backlog: 2048
  daemon: True
  limit_request_line: 4094
  timeout: 30
  raw_env: []
  pidfile: logs/gunicorn.pid
  worker_tmp_dir: None
  user: 1004
  umask: 0
  proxy_protocol: False
  proxy_allow_ips: ['127.0.0.1']
  when_ready: <function WhenReady.when_ready at 0x7f3c022f27b8>
  pre_fork: <function Prefork.pre_fork at 0x7f3c022f2950>
  post_worker_init: <function PostWorkerInit.post_worker_init at 0x7f3c022f2c80>
  worker_abort: <function WorkerAbort.worker_abort at 0x7f3c022fc048>
  post_request: <function PostRequest.post_request at 0x7f3c022fc488>
  keepalive: 2
  django_settings: None
  ssl_version: 3
  tmp_upload_dir: None
  capture_output: False
  limit_request_fields: 100
  limit_request_field_size: 8190
  proc_name: None
  accesslog: /home/django/source/edc-pharma/logs/gunicorn-access.log
  access_log_format: %(h)s %(l)s %(u)s %(t)s "%(r)s" %(s)s %(b)s "%(f)s" "%(a)s"
  loglevel: debug
  syslog: False
  syslog_prefix: None
  syslog_facility: user
  cert_reqs: 0
  workers: 1
  worker_class: sync
[2016-11-03 13:14:35 +0200] [10889] [INFO] Starting gunicorn 19.6.0
[2016-11-03 13:14:35 +0200] [10889] [DEBUG] Arbiter booted
[2016-11-03 13:14:35 +0200] [10889] [INFO] Listening at: http://127.0.0.1:9000 (10889)
[2016-11-03 13:14:35 +0200] [10889] [INFO] Using worker: sync
[2016-11-03 13:14:35 +0200] [10892] [INFO] Booting worker with pid: 10892
[2016-11-03 13:14:35 +0200] [10889] [DEBUG] 1 workers
[2016-11-03 13:14:35 +0200] [10892] [ERROR] Exception in worker process
Traceback (most recent call last):
  File "/home/django/.virtualenvs/edc-pharma/lib/python3.5/site-packages/gunicorn/arbiter.py", line 557, in spawn_worker
    worker.init_process()
  File "/home/django/.virtualenvs/edc-pharma/lib/python3.5/site-packages/gunicorn/workers/base.py", line 126, in init_process
    self.load_wsgi()
  File "/home/django/.virtualenvs/edc-pharma/lib/python3.5/site-packages/gunicorn/workers/base.py", line 136, in load_wsgi
    self.wsgi = self.app.wsgi()
  File "/home/django/.virtualenvs/edc-pharma/lib/python3.5/site-packages/gunicorn/app/base.py", line 67, in wsgi
    self.callable = self.load()
  File "/home/django/.virtualenvs/edc-pharma/lib/python3.5/site-packages/gunicorn/app/wsgiapp.py", line 65, in load
    return self.load_wsgiapp()
  File "/home/django/.virtualenvs/edc-pharma/lib/python3.5/site-packages/gunicorn/app/wsgiapp.py", line 52, in load_wsgiapp
    return util.import_app(self.app_uri)
  File "/home/django/.virtualenvs/edc-pharma/lib/python3.5/site-packages/gunicorn/util.py", line 357, in import_app
    __import__(module)
  File "/home/django/source/edc-pharma/edc_pharma/wsgi.py", line 16, in <module>
    application = get_wsgi_application()
  File "/home/django/.virtualenvs/edc-pharma/lib/python3.5/site-packages/django/core/wsgi.py", line 13, in get_wsgi_application
    django.setup(set_prefix=False)
  File "/home/django/.virtualenvs/edc-pharma/lib/python3.5/site-packages/django/__init__.py", line 22, in setup
    configure_logging(settings.LOGGING_CONFIG, settings.LOGGING)
  File "/home/django/.virtualenvs/edc-pharma/lib/python3.5/site-packages/django/conf/__init__.py", line 53, in __getattr__
    self._setup(name)
  File "/home/django/.virtualenvs/edc-pharma/lib/python3.5/site-packages/django/conf/__init__.py", line 41, in _setup
    self._wrapped = Settings(settings_module)
  File "/home/django/.virtualenvs/edc-pharma/lib/python3.5/site-packages/django/conf/__init__.py", line 97, in __init__
    mod = importlib.import_module(self.SETTINGS_MODULE)
  File "/home/django/.virtualenvs/edc-pharma/lib/python3.5/importlib/__init__.py", line 126, in import_module
    return _bootstrap._gcd_import(name[level:], package, level)
  File "/home/django/source/edc-pharma/edc_pharma/settings.py", line 95
    'NAME': 'pharma',
          ^
SyntaxError: invalid syntax
[2016-11-03 13:14:35 +0200] [10892] [INFO] Worker exiting (pid: 10892)
[2016-11-03 13:14:35 +0200] [10889] [INFO] Shutting down: Master
[2016-11-03 13:14:35 +0200] [10889] [INFO] Reason: Worker failed to boot.
[2016-11-03 13:15:29 +0200] [10909] [DEBUG] Current configuration:
  django_settings: None
  keyfile: None
  daemon: True
  do_handshake_on_connect: False
  check_config: False
  post_request: <function PostRequest.post_request at 0x7ff4be57f488>
  statsd_prefix: 
  pre_fork: <function Prefork.pre_fork at 0x7ff4be575950>
  raw_env: []
  timeout: 30
  pidfile: logs/gunicorn.pid
  access_log_format: %(h)s %(l)s %(u)s %(t)s "%(r)s" %(s)s %(b)s "%(f)s" "%(a)s"
  on_exit: <function OnExit.on_exit at 0x7ff4be57f950>
  worker_tmp_dir: None
  spew: False
  pre_exec: <function PreExec.pre_exec at 0x7ff4be57f1e0>
  umask: 0
  limit_request_field_size: 8190
  certfile: None
  preload_app: False
  pre_request: <function PreRequest.pre_request at 0x7ff4be57f378>
  syslog_prefix: None
  ciphers: TLSv1
  pythonpath: None
  paste: None
  worker_class: sync
  max_requests_jitter: 0
  loglevel: debug
  threads: 1
  on_starting: <function OnStarting.on_starting at 0x7ff4be575488>
  default_proc_name: edc_pharma.wsgi
  graceful_timeout: 30
  errorlog: /home/django/source/edc-pharma/logs/gunicorn-error.log
  worker_abort: <function WorkerAbort.worker_abort at 0x7ff4be57f048>
  backlog: 2048
  proc_name: None
  limit_request_line: 4094
  statsd_host: None
  when_ready: <function WhenReady.when_ready at 0x7ff4be5757b8>
  proxy_protocol: False
  accesslog: /home/django/source/edc-pharma/logs/gunicorn-access.log
  post_fork: <function Postfork.post_fork at 0x7ff4be575ae8>
  cert_reqs: 0
  suppress_ragged_eofs: True
  enable_stdio_inheritance: False
  workers: 1
  secure_scheme_headers: {'X-FORWARDED-SSL': 'on', 'X-FORWARDED-PROTOCOL': 'ssl', 'X-FORWARDED-PROTO': 'https'}
  bind: ['127.0.0.1:9000']
  keepalive: 2
  on_reload: <function OnReload.on_reload at 0x7ff4be575620>
  worker_int: <function WorkerInt.worker_int at 0x7ff4be575e18>
  worker_exit: <function WorkerExit.worker_exit at 0x7ff4be57f620>
  tmp_upload_dir: None
  proxy_allow_ips: ['127.0.0.1']
  logconfig: None
  reload: False
  post_worker_init: <function PostWorkerInit.post_worker_init at 0x7ff4be575c80>
  capture_output: False
  syslog_addr: udp://localhost:514
  sendfile: None
  chdir: /home/django/source/edc-pharma
  user: 1004
  group: 1004
  forwarded_allow_ips: ['127.0.0.1']
  logger_class: gunicorn.glogging.Logger
  syslog_facility: user
  worker_connections: 1000
  ca_certs: None
  nworkers_changed: <function NumWorkersChanged.nworkers_changed at 0x7ff4be57f7b8>
  limit_request_fields: 100
  ssl_version: 3
  syslog: False
  max_requests: 0
  config: gunicorn.conf.py
[2016-11-03 13:15:29 +0200] [10909] [INFO] Starting gunicorn 19.6.0
[2016-11-03 13:15:29 +0200] [10909] [DEBUG] Arbiter booted
[2016-11-03 13:15:29 +0200] [10909] [INFO] Listening at: http://127.0.0.1:9000 (10909)
[2016-11-03 13:15:29 +0200] [10909] [INFO] Using worker: sync
[2016-11-03 13:15:29 +0200] [10914] [INFO] Booting worker with pid: 10914
[2016-11-03 13:15:30 +0200] [10909] [DEBUG] 1 workers
[2016-11-03 13:15:30 +0200] [10914] [ERROR] Exception in worker process
Traceback (most recent call last):
  File "/home/django/.virtualenvs/edc-pharma/lib/python3.5/site-packages/gunicorn/arbiter.py", line 557, in spawn_worker
    worker.init_process()
  File "/home/django/.virtualenvs/edc-pharma/lib/python3.5/site-packages/gunicorn/workers/base.py", line 126, in init_process
    self.load_wsgi()
  File "/home/django/.virtualenvs/edc-pharma/lib/python3.5/site-packages/gunicorn/workers/base.py", line 136, in load_wsgi
    self.wsgi = self.app.wsgi()
  File "/home/django/.virtualenvs/edc-pharma/lib/python3.5/site-packages/gunicorn/app/base.py", line 67, in wsgi
    self.callable = self.load()
  File "/home/django/.virtualenvs/edc-pharma/lib/python3.5/site-packages/gunicorn/app/wsgiapp.py", line 65, in load
    return self.load_wsgiapp()
  File "/home/django/.virtualenvs/edc-pharma/lib/python3.5/site-packages/gunicorn/app/wsgiapp.py", line 52, in load_wsgiapp
    return util.import_app(self.app_uri)
  File "/home/django/.virtualenvs/edc-pharma/lib/python3.5/site-packages/gunicorn/util.py", line 357, in import_app
    __import__(module)
  File "/home/django/source/edc-pharma/edc_pharma/wsgi.py", line 16, in <module>
    application = get_wsgi_application()
  File "/home/django/.virtualenvs/edc-pharma/lib/python3.5/site-packages/django/core/wsgi.py", line 13, in get_wsgi_application
    django.setup(set_prefix=False)
  File "/home/django/.virtualenvs/edc-pharma/lib/python3.5/site-packages/django/__init__.py", line 22, in setup
    configure_logging(settings.LOGGING_CONFIG, settings.LOGGING)
  File "/home/django/.virtualenvs/edc-pharma/lib/python3.5/site-packages/django/conf/__init__.py", line 53, in __getattr__
    self._setup(name)
  File "/home/django/.virtualenvs/edc-pharma/lib/python3.5/site-packages/django/conf/__init__.py", line 41, in _setup
    self._wrapped = Settings(settings_module)
  File "/home/django/.virtualenvs/edc-pharma/lib/python3.5/site-packages/django/conf/__init__.py", line 116, in __init__
    raise ImproperlyConfigured("The SECRET_KEY setting must not be empty.")
django.core.exceptions.ImproperlyConfigured: The SECRET_KEY setting must not be empty.
[2016-11-03 13:15:30 +0200] [10914] [INFO] Worker exiting (pid: 10914)
[2016-11-03 13:15:30 +0200] [10909] [INFO] Shutting down: Master
[2016-11-03 13:15:30 +0200] [10909] [INFO] Reason: Worker failed to boot.
[2016-11-03 13:17:50 +0200] [10936] [DEBUG] Current configuration:
  secure_scheme_headers: {'X-FORWARDED-PROTO': 'https', 'X-FORWARDED-SSL': 'on', 'X-FORWARDED-PROTOCOL': 'ssl'}
  ciphers: TLSv1
  capture_output: False
  reload: False
  worker_connections: 1000
  sendfile: None
  chdir: /home/django/source/edc-pharma
  daemon: True
  pidfile: logs/gunicorn.pid
  paste: None
  proxy_protocol: False
  post_fork: <function Postfork.post_fork at 0x7fcd0238eae8>
  syslog: False
  syslog_prefix: None
  limit_request_field_size: 8190
  syslog_facility: user
  on_starting: <function OnStarting.on_starting at 0x7fcd0238e488>
  on_reload: <function OnReload.on_reload at 0x7fcd0238e620>
  cert_reqs: 0
  worker_exit: <function WorkerExit.worker_exit at 0x7fcd02398620>
  nworkers_changed: <function NumWorkersChanged.nworkers_changed at 0x7fcd023987b8>
  on_exit: <function OnExit.on_exit at 0x7fcd02398950>
  user: 1004
  pythonpath: None
  proxy_allow_ips: ['127.0.0.1']
  check_config: False
  keyfile: None
  certfile: None
  graceful_timeout: 30
  tmp_upload_dir: None
  loglevel: debug
  pre_fork: <function Prefork.pre_fork at 0x7fcd0238e950>
  post_worker_init: <function PostWorkerInit.post_worker_init at 0x7fcd0238ec80>
  umask: 0
  forwarded_allow_ips: ['127.0.0.1']
  ca_certs: None
  pre_exec: <function PreExec.pre_exec at 0x7fcd023981e0>
  worker_class: sync
  group: 1004
  access_log_format: %(h)s %(l)s %(u)s %(t)s "%(r)s" %(s)s %(b)s "%(f)s" "%(a)s"
  logconfig: None
  ssl_version: 3
  statsd_prefix: 
  default_proc_name: edc_pharma.wsgi
  accesslog: /home/django/source/edc-pharma/logs/gunicorn-access.log
  errorlog: /home/django/source/edc-pharma/logs/gunicorn-error.log
  statsd_host: None
  workers: 1
  threads: 1
  max_requests: 0
  keepalive: 2
  worker_int: <function WorkerInt.worker_int at 0x7fcd0238ee18>
  pre_request: <function PreRequest.pre_request at 0x7fcd02398378>
  logger_class: gunicorn.glogging.Logger
  django_settings: None
  config: gunicorn.conf.py
  preload_app: False
  bind: ['127.0.0.1:9000']
  backlog: 2048
  when_ready: <function WhenReady.when_ready at 0x7fcd0238e7b8>
  post_request: <function PostRequest.post_request at 0x7fcd02398488>
  limit_request_fields: 100
  suppress_ragged_eofs: True
  limit_request_line: 4094
  spew: False
  worker_abort: <function WorkerAbort.worker_abort at 0x7fcd02398048>
  timeout: 30
  enable_stdio_inheritance: False
  do_handshake_on_connect: False
  proc_name: None
  syslog_addr: udp://localhost:514
  raw_env: []
  worker_tmp_dir: None
  max_requests_jitter: 0
[2016-11-03 13:17:50 +0200] [10936] [INFO] Starting gunicorn 19.6.0
[2016-11-03 13:17:50 +0200] [10936] [DEBUG] Arbiter booted
[2016-11-03 13:17:50 +0200] [10936] [INFO] Listening at: http://127.0.0.1:9000 (10936)
[2016-11-03 13:17:50 +0200] [10936] [INFO] Using worker: sync
[2016-11-03 13:17:50 +0200] [10939] [INFO] Booting worker with pid: 10939
[2016-11-03 13:17:50 +0200] [10936] [DEBUG] 1 workers
[2016-11-03 13:17:53 +0200] [10939] [DEBUG] GET /
[2016-11-03 13:17:56 +0200] [10939] [DEBUG] GET /admin/
[2016-11-03 13:19:18 +0200] [10936] [INFO] Handling signal: term
[2016-11-03 13:19:18 +0200] [10939] [INFO] Worker exiting (pid: 10939)
[2016-11-03 13:19:18 +0200] [10936] [INFO] Shutting down: Master
[2016-11-03 13:19:19 +0200] [10967] [DEBUG] Current configuration:
  on_reload: <function OnReload.on_reload at 0x7fe7349c4620>
  post_worker_init: <function PostWorkerInit.post_worker_init at 0x7fe7349c4c80>
  ciphers: TLSv1
  worker_tmp_dir: None
  proc_name: None
  spew: False
  raw_env: []
  access_log_format: %(h)s %(l)s %(u)s %(t)s "%(r)s" %(s)s %(b)s "%(f)s" "%(a)s"
  syslog_addr: udp://localhost:514
  config: gunicorn.conf.py
  keepalive: 2
  worker_int: <function WorkerInt.worker_int at 0x7fe7349c4e18>
  worker_abort: <function WorkerAbort.worker_abort at 0x7fe7349ce048>
  check_config: False
  statsd_host: None
  ca_certs: None
  pre_exec: <function PreExec.pre_exec at 0x7fe7349ce1e0>
  nworkers_changed: <function NumWorkersChanged.nworkers_changed at 0x7fe7349ce7b8>
  suppress_ragged_eofs: True
  preload_app: False
  user: 1004
  logger_class: gunicorn.glogging.Logger
  threads: 1
  worker_connections: 1000
  max_requests: 0
  forwarded_allow_ips: ['127.0.0.1']
  paste: None
  accesslog: /home/django/source/edc-pharma/logs/gunicorn-access.log
  logconfig: None
  syslog: False
  workers: 1
  timeout: 30
  on_exit: <function OnExit.on_exit at 0x7fe7349ce950>
  limit_request_fields: 100
  worker_exit: <function WorkerExit.worker_exit at 0x7fe7349ce620>
  chdir: /home/django/source/edc-pharma
  pythonpath: None
  proxy_allow_ips: ['127.0.0.1']
  worker_class: sync
  max_requests_jitter: 0
  graceful_timeout: 30
  keyfile: None
  certfile: None
  ssl_version: 3
  cert_reqs: 0
  on_starting: <function OnStarting.on_starting at 0x7fe7349c4488>
  when_ready: <function WhenReady.when_ready at 0x7fe7349c47b8>
  post_fork: <function Postfork.post_fork at 0x7fe7349c4ae8>
  pre_request: <function PreRequest.pre_request at 0x7fe7349ce378>
  post_request: <function PostRequest.post_request at 0x7fe7349ce488>
  sendfile: None
  errorlog: /home/django/source/edc-pharma/logs/gunicorn-error.log
  loglevel: debug
  syslog_prefix: None
  syslog_facility: user
  do_handshake_on_connect: False
  daemon: True
  pidfile: logs/gunicorn.pid
  group: 1004
  umask: 0
  tmp_upload_dir: None
  pre_fork: <function Prefork.pre_fork at 0x7fe7349c4950>
  proxy_protocol: False
  bind: ['127.0.0.1:9000']
  backlog: 2048
  limit_request_field_size: 8190
  enable_stdio_inheritance: False
  limit_request_line: 4094
  capture_output: False
  django_settings: None
  default_proc_name: edc_pharma.wsgi
  statsd_prefix: 
  reload: False
  secure_scheme_headers: {'X-FORWARDED-PROTO': 'https', 'X-FORWARDED-PROTOCOL': 'ssl', 'X-FORWARDED-SSL': 'on'}
[2016-11-03 13:19:19 +0200] [10967] [INFO] Starting gunicorn 19.6.0
[2016-11-03 13:19:19 +0200] [10967] [DEBUG] Arbiter booted
[2016-11-03 13:19:19 +0200] [10967] [INFO] Listening at: http://127.0.0.1:9000 (10967)
[2016-11-03 13:19:19 +0200] [10967] [INFO] Using worker: sync
[2016-11-03 13:19:19 +0200] [10970] [INFO] Booting worker with pid: 10970
[2016-11-03 13:19:19 +0200] [10967] [DEBUG] 1 workers
